Workbook

Sheet Info
B3: Geopolitical Shocks & TASE Hospitality Stocks

Sheet Data
A1: Date | B1: TA125 | C1: Fattal | D1: Isrotel | E1: Dan | F1: TA125_Daily | G1: Fattal_Daily | H1: Isrotel_Daily | I1: Dan_Daily
A2: 46142 | B2: 4313.88 | C2: 73500 | D2: 15390 | E2: 2722 | F2: =B2/B3-1 -> 0.00034319636 | G2: =C2/C3-1 -> 0.002728513 | H2: =D2/D3-1 -> -0.00064935065 | I2: =E2/E3-1 -> -0.041549296
A3: 46141 | B3: 4312.4 | C3: 73300 | D3: 15400 | E3: 2840 | F3: =B3/B4-1 -> 0.012818766 | G3: =C3/C4-1 -> 0.0013661202 | H3: =D3/D4-1 -> 0 | I3: =E3/E4-1 -> -0.010452962
A4: 46140 | B4: 4257.82 | C4: 73200 | D4: 15400 | E4: 2870 | F4: =B4/B5-1 -> -0.0031139373 | G4: =C4/C5-1 -> -0.003403676 | H4: =D4/D5-1 -> -0.012820513 | I4: =E4/E5-1 -> -0.010344828
A5: 46139 | B5: 4271.12 | C5: 73450 | D5: 15600 | E5: 2900 | F5: =B5/B6-1 -> -0.00080242365 | G5: =C5/C6-1 -> 0.035236082 | H5: =D5/D6-1 -> 0.011017498 | I5: =E5/E6-1 -> 0
A6: 46136 | B6: 4274.55 | C6: 70950 | D6: 15430 | E6: 2900 | F6: =B6/B7-1 -> -0.012361225 | G6: =C6/C7-1 -> -0.010460251 | H6: =D6/D7-1 -> -0.019071837 | I6: =E6/E7-1 -> 0.0017271157
A7: 46135 | B7: 4328.05 | C7: 71700 | D7: 15730 | E7: 2895 | F7: =B7/B8-1 -> 4.1590898e-05 | G7: =C7/C8-1 -> 0.019914651 | H7: =D7/D8-1 -> -0.0069444444 | I7: =E7/E8-1 -> -0.00069036935
A8: 46132 | B8: 4327.87 | C8: 70300 | D8: 15840 | E8: 2897 | F8: =B8/B9-1 -> 0.0043722137 | G8: =C8/C9-1 -> 0.0129683 | H8: =D8/D9-1 -> 0.010204082 | I8: =E8/E9-1 -> 0
A9: 46129 | B9: 4309.03 | C9: 69400 | D9: 15680 | E9: 2897 | F9: =B9/B10-1 -> 0.010591317 | G9: =C9/C10-1 -> 0.032738095 | H9: =D9/D10-1 -> 0.042553191 | I9: =E9/E10-1 -> 0.0052047189
A10: 46128 | B10: 4263.87 | C10: 67200 | D10: 15040 | E10: 2882 | F10: =B10/B11-1 -> -0.010895788 | G10: =C10/C11-1 -> -0.0098718138 | H10: =D10/D11-1 -> -0.025906736 | I10: =E10/E11-1 -> -0.042524917
A11: 46127 | B11: 4310.84 | C11: 67870 | D11: 15440 | E11: 3010 | F11: =B11/B12-1 -> -0.0055915923 | G11: =C11/C12-1 -> 0.029893778 | H11: =D11/D12-1 -> -0.01025641 | I11: =E11/E12-1 -> 0
A12: 46126 | B12: 4335.08 | C12: 65900 | D12: 15600 | E12: 3010 | F12: =B12/B13-1 -> 0.014518937 | G12: =C12/C13-1 -> 0.057784912 | H12: =D12/D13-1 -> 0.019607843 | I12: =E12/E13-1 -> 0
A13: 46125 | B13: 4273.04 | C13: 62300 | D13: 15300 | E13: 3010 | F13: =B13/B14-1 -> -0.014456653 | G13: =C13/C14-1 -> -0.017040076 | H13: =D13/D14-1 -> -0.0097087379 | I13: =E13/E14-1 -> 0
... A893: 44809 | B893: 2053.2 | C893: 40230 | D893: 10030 | E893: 2919 | F893: =B893/B894-1 -> -0.00090508306 | G893: =C893/C894-1 -> 0.0032418953 | H893: =D893/D894-1 -> -0.0019900498 | I893: =E893/E894-1 -> -0.0023923445
A894: 44808 | B894: 2055.06 | C894: 40100 | D894: 10050 | E894: 2926 | F894: 0 | G894: 0 | H894: 0 | I894: 0

Sheet Fattal
A1: Fattal — Event Study (market model, single-variable regression)
A3: Parameters
A4: Estimation window (max days) | B4: 252
A5: Event window (days each side) | B5: 10
A6: Significance |t| > | B6: 1.96
A8: Events
A9: # | B9: Event date | C9: TASE t=0 | D9: Sign | E9: Description
A10: 1 | B10: 45206 | C10: =IF(WEEKDAY(B10)=6,B10+2,IF(WEEKDAY(B10)=7,B10+1,B10)) -> 45207 | D10: - | E10: Hamas attack; Israel declares war
A11: 2 | B11: 45252 | C11: =IF(WEEKDAY(B11)=6,B11+2,IF(WEEKDAY(B11)=7,B11+1,B11)) -> 45252 | D11: + | E11: First hostage truce (105 freed)
A12: 3 | B12: 45396 | C12: =IF(WEEKDAY(B12)=6,B12+2,IF(WEEKDAY(B12)=7,B12+1,B12)) -> 45396 | D12: - | E12: Iran first direct attack
A13: 4 | B13: 45504 | C13: =IF(WEEKDAY(B13)=6,B13+2,IF(WEEKDAY(B13)=7,B13+1,B13)) -> 45504 | D13: - | E13: Haniyeh assassinated in Tehran
A14: 5 | B14: 45566 | C14: 45571 | D14: - | E14: Iran second attack (~180 missiles)
A15: 6 | B15: 45623 | C15: =IF(WEEKDAY(B15)=6,B15+2,IF(WEEKDAY(B15)=7,B15+1,B15)) -> 45623 | D15: + | E15: Israel-Lebanon ceasefire
A16: 7 | B16: 45672 | C16: =IF(WEEKDAY(B16)=6,B16+2,IF(WEEKDAY(B16)=7,B16+1,B16)) -> 45672 | D16: + | E16: Gaza ceasefire (33 hostages)
A17: 8 | B17: 45789 | C17: 45789 | D17: + | E17: Edan Alexander released
A18: 9 | B18: 45821 | C18: =IF(WEEKDAY(B18)=6,B18+2,IF(WEEKDAY(B18)=7,B18+1,B18)) -> 45823 | D18: - | E18: 12-Day War begins
A19: 10 | B19: 45939 | C19: =IF(WEEKDAY(B19)=6,B19+2,IF(WEEKDAY(B19)=7,B19+1,B19)) -> 45939 | D19: + | E19: Sharm el-Sheikh deal
A20: 11 | B20: 46081 | C20: =IF(WEEKDAY(B20)=7, B20+2, IF(WEEKDAY(B20)=1, B20+1, B20)) -> 46083 | D20: - | E20: 2026 Israel-Iran war begins
A21: 12 | B21: 46120 | C21: 46121 | D21: + | E21: Pakistan-brokered ceasefire
A23: Model info & statistics — market-model regression (stock daily return on TA-125 daily return; 252-day estimation window). Intercept = α (INTERCEPT), b1 = β (SLOPE), R² (RSQ), sey = standard error of the estimate (STEYX).
A24: # | B24: Event t=0 (adj) | C24: Event point | D24: Window | E24: a (intercept) | F24: b1 (TA125) | G24: (unused) | H24: R2 | I24: sey
A25: =A10 -> 1 | B25: =IF(WEEKDAY(B10)=6,B10+2,IF(WEEKDAY(B10)=7,B10+1,B10)) -> 45207 | C25: =IFERROR(MATCH(B25,Data!$A$2:$A$718,0),MATCH(B25,Data!$A$2:$A$718,-1)) -> 630 | D25: =MIN($B$4,COUNTA(Data!$A:$A)-1-(C25+11)+1) -> 252 | E25: =INTERCEPT(OFFSET(Data!$G$1,C25+11,0,D25,1),OFFSET(Data!$F$1,C25+11,0,D25,1)) -> 0.00028642491 | F25: =SLOPE(OFFSET(Data!$G$1,C25+11,0,D25,1),OFFSET(Data!$F$1,C25+11,0,D25,1)) -> 1.4028615 | H25: =RSQ(OFFSET(Data!$G$1,C25+11,0,D25,1),OFFSET(Data!$F$1,C25+11,0,D25,1)) -> 0.39123992 | I25: =STEYX(OFFSET(Data!$G$1,C25+11,0,D25,1),OFFSET(Data!$F$1,C25+11,0,D25,1)) -> 0.018253549
A26: =A11 -> 2 | B26: =IF(WEEKDAY(C11)=6,C11+2,IF(WEEKDAY(C11)=7,C11+1,C11)) -> 45252 | C26: =IFERROR(MATCH(B26,Data!$A$2:$A$718,0),MATCH(B26,Data!$A$2:$A$718,-1)) -> 597 | D26: =MIN($B$4,875-(C26+11)+1) -> 252 | E26: =INTERCEPT(OFFSET(Data!$G$1,C26+11,0,D26,1),OFFSET(Data!$F$1,C26+11,0,D26,1)) -> 0.0011347158 | F26: =SLOPE(OFFSET(Data!$G$1,C26+11,0,D26,1),OFFSET(Data!$F$1,C26+11,0,D26,1)) -> 1.3515287 | H26: =RSQ(OFFSET(Data!$G$1,C26+11,0,D26,1),OFFSET(Data!$F$1,C26+11,0,D26,1)) -> 0.43759662 | I26: =STEYX(OFFSET(Data!$G$1,C26+11,0,D26,1),OFFSET(Data!$F$1,C26+11,0,D26,1)) -> 0.017779338
A27: =A12 -> 3 | B27: =IF(WEEKDAY(C12)=6,C12+2,IF(WEEKDAY(C12)=7,C12+1,C12)) -> 45396 | C27: =IFERROR(MATCH(B27,Data!$A$2:$A$718,0),MATCH(B27,Data!$A$2:$A$718,-1)) -> 497 | D27: =MIN($B$4,875-(C27+11)) -> 252 | E27: =INTERCEPT(OFFSET(Data!$G$1,C27+11,0,D27,1),OFFSET(Data!$F$1,C27+11,0,D27,1)) -> 0.0011870735 | F27: =SLOPE(OFFSET(Data!$G$1,C27+11,0,D27,1),OFFSET(Data!$F$1,C27+11,0,D27,1)) -> 1.1217334 | H27: =RSQ(OFFSET(Data!$G$1,C27+11,0,D27,1),OFFSET(Data!$F$1,C27+11,0,D27,1)) -> 0.37528432 | I27: =STEYX(OFFSET(Data!$G$1,C27+11,0,D27,1),OFFSET(Data!$F$1,C27+11,0,D27,1)) -> 0.015674184
A28: =A13 -> 4 | B28: =IF(WEEKDAY(C13)=6,C13+2,IF(WEEKDAY(C13)=7,C13+1,C13)) -> 45504 | C28: =IFERROR(MATCH(B28,Data!$A$2:$A$718,0),MATCH(B28,Data!$A$2:$A$718,-1)) -> 427 | D28: =MIN($B$4,717-(C28+11)) -> 252 | E28: =INTERCEPT(OFFSET(Data!$G$1,C28+11,0,D28,1),OFFSET(Data!$F$1,C28+11,0,D28,1)) -> 1.2483265e-05 | F28: =SLOPE(OFFSET(Data!$G$1,C28+11,0,D28,1),OFFSET(Data!$F$1,C28+11,0,D28,1)) -> 1.1850264 | H28: =RSQ(OFFSET(Data!$G$1,C28+11,0,D28,1),OFFSET(Data!$F$1,C28+11,0,D28,1)) -> 0.44518874 | I28: =STEYX(OFFSET(Data!$G$1,C28+11,0,D28,1),OFFSET(Data!$F$1,C28+11,0,D28,1)) -> 0.014435731
A29: =A14 -> 5 | B29: =IF(WEEKDAY(C14)=6,C14+2,IF(WEEKDAY(C14)=7,C14+1,C14)) -> 45571 | C29: =IFERROR(MATCH(B29,Data!$A$2:$A$718,0),MATCH(B29,Data!$A$2:$A$718,-1)) -> 383 | D29: =MIN($B$4,717-(C29+11)) -> 252 | E29: =INTERCEPT(OFFSET(Data!$G$1,C29+11,0,D29,1),OFFSET(Data!$F$1,C29+11,0,D29,1)) -> 0.00015708143 | F29: =SLOPE(OFFSET(Data!$G$1,C29+11,0,D29,1),OFFSET(Data!$F$1,C29+11,0,D29,1)) -> 1.2128881 | H29: =RSQ(OFFSET(Data!$G$1,C29+11,0,D29,1),OFFSET(Data!$F$1,C29+11,0,D29,1)) -> 0.4511336 | I29: =STEYX(OFFSET(Data!$G$1,C29+11,0,D29,1),OFFSET(Data!$F$1,C29+11,0,D29,1)) -> 0.014684599
A30: =A15 -> 6 | B30: =IF(WEEKDAY(C15)=6,C15+2,IF(WEEKDAY(C15)=7,C15+1,C15)) -> 45623 | C30: =IFERROR(MATCH(B30,Data!$A$2:$A$718,0),MATCH(B30,Data!$A$2:$A$718,-1)) -> 349 | D30: =MIN($B$4,717-(C30+11)) -> 252 | E30: =INTERCEPT(OFFSET(Data!$G$1,C30+11,0,D30,1),OFFSET(Data!$F$1,C30+11,0,D30,1)) -> -0.00014222531 | F30: =SLOPE(OFFSET(Data!$G$1,C30+11,0,D30,1),OFFSET(Data!$F$1,C30+11,0,D30,1)) -> 1.2857621 | H30: =RSQ(OFFSET(Data!$G$1,C30+11,0,D30,1),OFFSET(Data!$F$1,C30+11,0,D30,1)) -> 0.40488194 | I30: =STEYX(OFFSET(Data!$G$1,C30+11,0,D30,1),OFFSET(Data!$F$1,C30+11,0,D30,1)) -> 0.014930032
A31: =A16 -> 7 | B31: =IF(WEEKDAY(C16)=6,C16+2,IF(WEEKDAY(C16)=7,C16+1,C16)) -> 45672 | C31: =IFERROR(MATCH(B31,Data!$A$2:$A$718,0),MATCH(B31,Data!$A$2:$A$718,-1)) -> 314 | D31: =MIN($B$4,717-(C31+11)) -> 252 | E31: =INTERCEPT(OFFSET(Data!$G$1,C31+11,0,D31,1),OFFSET(Data!$F$1,C31+11,0,D31,1)) -> -0.00019690886 | F31: =SLOPE(OFFSET(Data!$G$1,C31+11,0,D31,1),OFFSET(Data!$F$1,C31+11,0,D31,1)) -> 1.2085727 | H31: =RSQ(OFFSET(Data!$G$1,C31+11,0,D31,1),OFFSET(Data!$F$1,C31+11,0,D31,1)) -> 0.34698948 | I31: =STEYX(OFFSET(Data!$G$1,C31+11,0,D31,1),OFFSET(Data!$F$1,C31+11,0,D31,1)) -> 0.014935076
A32: =A17 -> 8 | B32: =IF(WEEKDAY(C17)=6,C17+2,IF(WEEKDAY(C17)=7,C17+1,C17)) -> 45789 | C32: =IFERROR(MATCH(B32,Data!$A$2:$A$718,0),MATCH(B32,Data!$A$2:$A$718,-1)) -> 234 | D32: =MIN($B$4,717-(C32+11)) -> 252 | E32: =INTERCEPT(OFFSET(Data!$G$1,C32+11,0,D32,1),OFFSET(Data!$F$1,C32+11,0,D32,1)) -> -0.0007467555 | F32: =SLOPE(OFFSET(Data!$G$1,C32+11,0,D32,1),OFFSET(Data!$F$1,C32+11,0,D32,1)) -> 1.112002 | H32: =RSQ(OFFSET(Data!$G$1,C32+11,0,D32,1),OFFSET(Data!$F$1,C32+11,0,D32,1)) -> 0.32834484 | I32: =STEYX(OFFSET(Data!$G$1,C32+11,0,D32,1),OFFSET(Data!$F$1,C32+11,0,D32,1)) -> 0.016032163
A33: =A18 -> 9 | B33: =IF(WEEKDAY(C18)=6,C18+2,IF(WEEKDAY(C18)=7,C18+1,C18)) -> 45823 | C33: =IFERROR(MATCH(B33,Data!$A$2:$A$718,0),MATCH(B33,Data!$A$2:$A$718,-1)) -> 212 | D33: =MIN($B$4,717-(C33+11)) -> 252 | E33: =INTERCEPT(OFFSET(Data!$G$1,C33+11,0,D33,1),OFFSET(Data!$F$1,C33+11,0,D33,1)) -> -0.0003824267 | F33: =SLOPE(OFFSET(Data!$G$1,C33+11,0,D33,1),OFFSET(Data!$F$1,C33+11,0,D33,1)) -> 1.1191461 | H33: =RSQ(OFFSET(Data!$G$1,C33+11,0,D33,1),OFFSET(Data!$F$1,C33+11,0,D33,1)) -> 0.33041799 | I33: =STEYX(OFFSET(Data!$G$1,C33+11,0,D33,1),OFFSET(Data!$F$1,C33+11,0,D33,1)) -> 0.015880047
A34: =A19 -> 10 | B34: =IF(WEEKDAY(C19)=6,C19+2,IF(WEEKDAY(C19)=7,C19+1,C19)) -> 45939 | C34: =IFERROR(MATCH(B34,Data!$A$2:$A$718,0),MATCH(B34,Data!$A$2:$A$718,-1)) -> 136 | D34: =MIN($B$4,717-(C34+11)) -> 252 | E34: =INTERCEPT(OFFSET(Data!$G$1,C34+11,0,D34,1),OFFSET(Data!$F$1,C34+11,0,D34,1)) -> -0.00082260592 | F34: =SLOPE(OFFSET(Data!$G$1,C34+11,0,D34,1),OFFSET(Data!$F$1,C34+11,0,D34,1)) -> 1.0944115 | H34: =RSQ(OFFSET(Data!$G$1,C34+11,0,D34,1),OFFSET(Data!$F$1,C34+11,0,D34,1)) -> 0.32052367 | I34: =STEYX(OFFSET(Data!$G$1,C34+11,0,D34,1),OFFSET(Data!$F$1,C34+11,0,D34,1)) -> 0.015956258
A35: =A20 -> 11 | B35: =IF(WEEKDAY(C20)=7, C20+2, IF(WEEKDAY(C20)=1, C20+1, C20)) -> 46083 | C35: =IFERROR(MATCH(B35,Data!$A$2:$A$718,0),MATCH(B35,Data!$A$2:$A$718,-1)) -> 37 | D35: =MIN($B$4,717-(C35+11)) -> 252 | E35: =INTERCEPT(OFFSET(Data!$G$1,C35+11,0,D35,1),OFFSET(Data!$F$1,C35+11,0,D35,1)) -> -0.00099985744 | F35: =SLOPE(OFFSET(Data!$G$1,C35+11,0,D35,1),OFFSET(Data!$F$1,C35+11,0,D35,1)) -> 1.0400682 | H35: =RSQ(OFFSET(Data!$G$1,C35+11,0,D35,1),OFFSET(Data!$F$1,C35+11,0,D35,1)) -> 0.34312822 | I35: =STEYX(OFFSET(Data!$G$1,C35+11,0,D35,1),OFFSET(Data!$F$1,C35+11,0,D35,1)) -> 0.015699861
A36: =A21 -> 12 | B36: =IF(WEEKDAY(C21)=7, C21+2, IF(WEEKDAY(C21)=1, C21+1, C21)) -> 46121 | C36: =IFERROR(MATCH(B36,Data!$A$2:$A$718,0),MATCH(B36,Data!$A$2:$A$718,-1)) -> 14 | D36: =MIN($B$4,717-(C36+11)) -> 252 | E36: =INTERCEPT(OFFSET(Data!$G$1,C36+11,0,D36,1),OFFSET(Data!$F$1,C36+11,0,D36,1)) -> -0.00096423103 | F36: =SLOPE(OFFSET(Data!$G$1,C36+11,0,D36,1),OFFSET(Data!$F$1,C36+11,0,D36,1)) -> 1.0115585 | H36: =RSQ(OFFSET(Data!$G$1,C36+11,0,D36,1),OFFSET(Data!$F$1,C36+11,0,D36,1)) -> 0.33478655 | I36: =STEYX(OFFSET(Data!$G$1,C36+11,0,D36,1),OFFSET(Data!$F$1,C36+11,0,D36,1)) -> 0.016206939
A38: Event windows [-10, +10] — AR = Actual − Expected; t = AR / sey; CAR = (1+CARprev)(1+AR)−1
A39: Event 1 | B39: =E10 -> Hamas attack; Israel declares war
A40: rel day | B40: weekday | C40: Date | D40: Actual | E40: Expected | F40: AR | G40: t-test | H40: Sig? | I40: CAR | L40: SIG?
A41: 10 | B41: =TEXT(WEEKDAY(C41),"ddd") -> Sun | C41: =OFFSET(Data!$A$1,$C$25-A41,0,1,1) -> 45221 | D41: =_xlfn.XLOOKUP(C41,Data!$A:$A,Data!$G:$G) -> -0.013732834 | E41: =$E$25+$F$25*_xlfn.XLOOKUP(C41,Data!$A:$A,Data!$F:$F) -> -0.035095035 | F41: =D41-E41 -> 0.021362201 | G41: =F41/$I$25 -> 1.170304 | H41: =IF(ABS(G41)<$B$6,"No","Yes") -> No | I41: =(1+I42)*(1+F41)-1 -> 0.050423102
A42: 9 | B42: =TEXT(WEEKDAY(C42),"ddd") -> Thu | C42: =OFFSET(Data!$A$1,$C$25-A42,0,1,1) -> 45218 | D42: =_xlfn.XLOOKUP(C42,Data!$A:$A,Data!$G:$G) -> -0.0058951288 | E42: =$E$25+$F$25*_xlfn.XLOOKUP(C42,Data!$A:$A,Data!$F:$F) -> -0.024808829 | F42: =D42-E42 -> 0.0189137 | G42: =F42/$I$25 -> 1.0361656 | H42: =IF(ABS(G42)<$B$6,"No","Yes") -> No | I42: =(1+I43)*(1+F42)-1 -> 0.028453081
A43: 8 | B43: =TEXT(WEEKDAY(C43),"ddd") -> Wed | C43: =OFFSET(Data!$A$1,$C$25-A43,0,1,1) -> 45217 | D43: =_xlfn.XLOOKUP(C43,Data!$A:$A,Data!$G:$G) -> 0.0056162246 | E43: =$E$25+$F$25*_xlfn.XLOOKUP(C43,Data!$A:$A,Data!$F:$F) -> 0.0079839157 | F43: =D43-E43 -> -0.0023676911 | G43: =F43/$I$25 -> -0.12971127 | H43: =IF(ABS(G43)<$B$6,"No","Yes") -> No | I43: =(1+I44)*(1+F43)-1 -> 0.0093623053
A44: 7 | B44: =TEXT(WEEKDAY(C44),"ddd") -> Tue | C44: =OFFSET(Data!$A$1,$C$25-A44,0,1,1) -> 45216 | D44: =_xlfn.XLOOKUP(C44,Data!$A:$A,Data!$G:$G) -> -0.013238916 | E44: =$E$25+$F$25*_xlfn.XLOOKUP(C44,Data!$A:$A,Data!$F:$F) -> -0.0052404938 | F44: =D44-E44 -> -0.0079984225 | G44: =F44/$I$25 -> -0.43818451 | H44: =IF(ABS(G44)<$B$6,"No","Yes") -> No | I44: =(1+I45)*(1+F44)-1 -> 0.011757835
...

Sheet Isrotel
A1: Isrotel — Event Study (market model, single-variable regression)
A3: Parameters
A4: Estimation window (max days) | B4: 252
A5: Event window (days each side) | B5: 10
A6: Significance |t| > | B6: 1.96
A8: Events
A9: # | B9: Event date | C9: TASE t=0 | D9: Sign | E9: Description
A10: 1 | B10: 45206 | C10: =IF(WEEKDAY(B10)=6,B10+2,IF(WEEKDAY(B10)=7,B10+1,B10)) -> 45207 | D10: - | E10: Hamas attack; Israel declares war
A11: 2 | B11: 45252 | C11: =IF(WEEKDAY(B11)=6,B11+2,IF(WEEKDAY(B11)=7,B11+1,B11)) -> 45252 | D11: + | E11: First hostage truce (105 freed)
A12: 3 | B12: 45396 | C12: =IF(WEEKDAY(B12)=6,B12+2,IF(WEEKDAY(B12)=7,B12+1,B12)) -> 45396 | D12: - | E12: Iran first direct attack
A13: 4 | B13: 45504 | C13: =IF(WEEKDAY(B13)=6,B13+2,IF(WEEKDAY(B13)=7,B13+1,B13)) -> 45504 | D13: - | E13: Haniyeh assassinated in Tehran
A14: 5 | B14: 45566 | C14: 45571 | D14: - | E14: Iran second attack (~180 missiles)
A15: 6 | B15: 45623 | C15: =IF(WEEKDAY(B15)=6,B15+2,IF(WEEKDAY(B15)=7,B15+1,B15)) -> 45623 | D15: + | E15: Israel-Lebanon ceasefire
A16: 7 | B16: 45672 | C16: =IF(WEEKDAY(B16)=6,B16+2,IF(WEEKDAY(B16)=7,B16+1,B16)) -> 45672 | D16: + | E16: Gaza ceasefire (33 hostages)
A17: 8 | B17: 45789 | C17: 45789 | D17: + | E17: Edan Alexander released
A18: 9 | B18: 45821 | C18: =IF(WEEKDAY(B18)=6,B18+2,IF(WEEKDAY(B18)=7,B18+1,B18)) -> 45823 | D18: - | E18: 12-Day War begins
A19: 10 | B19: 45939 | C19: =IF(WEEKDAY(B19)=6,B19+2,IF(WEEKDAY(B19)=7,B19+1,B19)) -> 45939 | D19: + | E19: Sharm el-Sheikh deal
A20: 11 | B20: 46081 | C20: =IF(WEEKDAY(B20)=7, B20+2, IF(WEEKDAY(B20)=1, B20+1, B20)) -> 46083 | D20: - | E20: 2026 Israel-Iran war begins
A21: 12 | B21: 46120 | C21: 46121 | D21: + | E21: Pakistan-brokered ceasefire
A23: Model info & statistics — market-model regression (stock daily return on TA-125 daily return; 252-day estimation window). Intercept = α (INTERCEPT), b1 = β (SLOPE), R² (RSQ), sey = standard error of the estimate (STEYX).
A24: # | B24: Event t=0 (adj) | C24: Event point | D24: Window | E24: a (intercept) | F24: b1 (TA125) | G24: (unused) | H24: R2 | I24: sey
A25: =A10 -> 1 | B25: =IF(WEEKDAY(C10)=6,C10+2,IF(WEEKDAY(C10)=7,C10+1,C10)) -> 45207 | C25: =IFERROR(MATCH(B25,Data!$A$2:$A$718,0),MATCH(B25,Data!$A$2:$A$718,-1)) -> 630 | D25: =MIN($B$4,COUNTA(Data!$A:$A)-1-(C25+11)+1) -> 252 | E25: =INTERCEPT(OFFSET(Data!$H$1,C25+11,0,D25,1),OFFSET(Data!$F$1,C25+11,0,D25,1)) -> -0.0012110107 | F25: =SLOPE(OFFSET(Data!$H$1,C25+11,0,D25,1),OFFSET(Data!$F$1,C25+11,0,D25,1)) -> 0.20242167 | H25: =RSQ(OFFSET(Data!$H$1,C25+11,0,D25,1),OFFSET(Data!$F$1,C25+11,0,D25,1)) -> 0.01394492 | I25: =STEYX(OFFSET(Data!$H$1,C25+11,0,D25,1),OFFSET(Data!$F$1,C25+11,0,D25,1)) -> 0.017755405
A26: =A11 -> 2 | B26: =IF(WEEKDAY(C11)=6,C11+2,IF(WEEKDAY(C11)=7,C11+1,C11)) -> 45252 | C26: =IFERROR(MATCH(B26,Data!$A$2:$A$718,0),MATCH(B26,Data!$A$2:$A$718,-1)) -> 597 | D26: =MIN($B$4,COUNTA(Data!$A:$A)-1-(C26+11)+1) -> 252 | E26: =INTERCEPT(OFFSET(Data!$H$1,C26+11,0,D26,1),OFFSET(Data!$F$1,C26+11,0,D26,1)) -> -0.00098359429 | F26: =SLOPE(OFFSET(Data!$H$1,C26+11,0,D26,1),OFFSET(Data!$F$1,C26+11,0,D26,1)) -> 0.32767133 | H26: =RSQ(OFFSET(Data!$H$1,C26+11,0,D26,1),OFFSET(Data!$F$1,C26+11,0,D26,1)) -> 0.042126226 | I26: =STEYX(OFFSET(Data!$H$1,C26+11,0,D26,1),OFFSET(Data!$F$1,C26+11,0,D26,1)) -> 0.018130911
A27: =A12 -> 3 | B27: =IF(WEEKDAY(C12)=6,C12+2,IF(WEEKDAY(C12)=7,C12+1,C12)) -> 45396 | C27: =IFERROR(MATCH(B27,Data!$A$2:$A$718,0),MATCH(B27,Data!$A$2:$A$718,-1)) -> 497 | D27: =MIN($B$4,COUNTA(Data!$A:$A)-1-(C27+11)+1) -> 252 | E27: =INTERCEPT(OFFSET(Data!$H$1,C27+11,0,D27,1),OFFSET(Data!$F$1,C27+11,0,D27,1)) -> 0.00067932195 | F27: =SLOPE(OFFSET(Data!$H$1,C27+11,0,D27,1),OFFSET(Data!$F$1,C27+11,0,D27,1)) -> 0.43617163 | H27: =RSQ(OFFSET(Data!$H$1,C27+11,0,D27,1),OFFSET(Data!$F$1,C27+11,0,D27,1)) -> 0.059081344 | I27: =STEYX(OFFSET(Data!$H$1,C27+11,0,D27,1),OFFSET(Data!$F$1,C27+11,0,D27,1)) -> 0.018851355
A28: =A13 -> 4 | B28: =IF(WEEKDAY(C13)=6,C13+2,IF(WEEKDAY(C13)=7,C13+1,C13)) -> 45504 | C28: =IFERROR(MATCH(B28,Data!$A$2:$A$718,0),MATCH(B28,Data!$A$2:$A$718,-1)) -> 427 | D28: =MIN($B$4,COUNTA(Data!$A:$A)-1-(C28+11)+1) -> 252 | E28: =INTERCEPT(OFFSET(Data!$H$1,C28+11,0,D28,1),OFFSET(Data!$F$1,C28+11,0,D28,1)) -> 5.7920211e-05 | F28: =SLOPE(OFFSET(Data!$H$1,C28+11,0,D28,1),OFFSET(Data!$F$1,C28+11,0,D28,1)) -> 0.52546814 | H28: =RSQ(OFFSET(Data!$H$1,C28+11,0,D28,1),OFFSET(Data!$F$1,C28+11,0,D28,1)) -> 0.122617 | I28: =STEYX(OFFSET(Data!$H$1,C28+11,0,D28,1),OFFSET(Data!$F$1,C28+11,0,D28,1)) -> 0.015338251
A29: =A14 -> 5 | B29: =IF(WEEKDAY(C14)=6,C14+2,IF(WEEKDAY(C14)=7,C14+1,C14)) -> 45571 | C29: =IFERROR(MATCH(B29,Data!$A$2:$A$718,0),MATCH(B29,Data!$A$2:$A$718,-1)) -> 383 | D29: =MIN($B$4,COUNTA(Data!$A:$A)-1-(C29+11)+1) -> 252 | E29: =INTERCEPT(OFFSET(Data!$H$1,C29+11,0,D29,1),OFFSET(Data!$F$1,C29+11,0,D29,1)) -> -7.0571051e-05 | F29: =SLOPE(OFFSET(Data!$H$1,C29+11,0,D29,1),OFFSET(Data!$F$1,C29+11,0,D29,1)) -> 0.67927325 | H29: =RSQ(OFFSET(Data!$H$1,C29+11,0,D29,1),OFFSET(Data!$F$1,C29+11,0,D29,1)) -> 0.17818153 | I29: =STEYX(OFFSET(Data!$H$1,C29+11,0,D29,1),OFFSET(Data!$F$1,C29+11,0,D29,1)) -> 0.016012595
A30: =A15 -> 6 | B30: =IF(WEEKDAY(C15)=6,C15+2,IF(WEEKDAY(C15)=7,C15+1,C15)) -> 45623 | C30: =IFERROR(MATCH(B30,Data!$A$2:$A$718,0),MATCH(B30,Data!$A$2:$A$718,-1)) -> 349 | D30: =MIN($B$4,COUNTA(Data!$A:$A)-1-(C30+11)+1) -> 252 | E30: =INTERCEPT(OFFSET(Data!$H$1,C30+11,0,D30,1),OFFSET(Data!$F$1,C30+11,0,D30,1)) -> -0.00015956978 | F30: =SLOPE(OFFSET(Data!$H$1,C30+11,0,D30,1),OFFSET(Data!$F$1,C30+11,0,D30,1)) -> 0.73853276 | H30: =RSQ(OFFSET(Data!$H$1,C30+11,0,D30,1),OFFSET(Data!$F$1,C30+11,0,D30,1)) -> 0.16363621 | I30: =STEYX(OFFSET(Data!$H$1,C30+11,0,D30,1),OFFSET(Data!$F$1,C30+11,0,D30,1)) -> 0.015991545
A31: =A16 -> 7 | B31: =IF(WEEKDAY(C16)=6,C16+2,IF(WEEKDAY(C16)=7,C16+1,C16)) -> 45672 | C31: =IFERROR(MATCH(B31,Data!$A$2:$A$718,0),MATCH(B31,Data!$A$2:$A$718,-1)) -> 314 | D31: =MIN($B$4,COUNTA(Data!$A:$A)-1-(C31+11)+1) -> 252 | E31: =INTERCEPT(OFFSET(Data!$H$1,C31+11,0,D31,1),OFFSET(Data!$F$1,C31+11,0,D31,1)) -> 0.00018442855 | F31: =SLOPE(OFFSET(Data!$H$1,C31+11,0,D31,1),OFFSET(Data!$F$1,C31+11,0,D31,1)) -> 0.73870749 | H31: =RSQ(OFFSET(Data!$H$1,C31+11,0,D31,1),OFFSET(Data!$F$1,C31+11,0,D31,1)) -> 0.14475234 | I31: =STEYX(OFFSET(Data!$H$1,C31+11,0,D31,1),OFFSET(Data!$F$1,C31+11,0,D31,1)) -> 0.01617478
A32: =A17 -> 8 | B32: =IF(WEEKDAY(C17)=6,C17+2,IF(WEEKDAY(C17)=7,C17+1,C17)) -> 45789 | C32: =IFERROR(MATCH(B32,Data!$A$2:$A$718,0),MATCH(B32,Data!$A$2:$A$718,-1)) -> 234 | D32: =MIN($B$4,COUNTA(Data!$A:$A)-1-(C32+11)+1) -> 252 | E32: =INTERCEPT(OFFSET(Data!$H$1,C32+11,0,D32,1),OFFSET(Data!$F$1,C32+11,0,D32,1)) -> -0.001197695 | F32: =SLOPE(OFFSET(Data!$H$1,C32+11,0,D32,1),OFFSET(Data!$F$1,C32+11,0,D32,1)) -> 0.80039724 | H32: =RSQ(OFFSET(Data!$H$1,C32+11,0,D32,1),OFFSET(Data!$F$1,C32+11,0,D32,1)) -> 0.20671225 | I32: =STEYX(OFFSET(Data!$H$1,C32+11,0,D32,1),OFFSET(Data!$F$1,C32+11,0,D32,1)) -> 0.015805794
A33: =A18 -> 9 | B33: =IF(WEEKDAY(C18)=6,C18+2,IF(WEEKDAY(C18)=7,C18+1,C18)) -> 45823 | C33: =IFERROR(MATCH(B33,Data!$A$2:$A$718,0),MATCH(B33,Data!$A$2:$A$718,-1)) -> 212 | D33: =MIN($B$4,COUNTA(Data!$A:$A)-1-(C33+11)+1) -> 252 | E33: =INTERCEPT(OFFSET(Data!$H$1,C33+11,0,D33,1),OFFSET(Data!$F$1,C33+11,0,D33,1)) -> -0.00087320992 | F33: =SLOPE(OFFSET(Data!$H$1,C33+11,0,D33,1),OFFSET(Data!$F$1,C33+11,0,D33,1)) -> 0.87301138 | H33: =RSQ(OFFSET(Data!$H$1,C33+11,0,D33,1),OFFSET(Data!$F$1,C33+11,0,D33,1)) -> 0.22455777 | I33: =STEYX(OFFSET(Data!$H$1,C33+11,0,D33,1),OFFSET(Data!$F$1,C33+11,0,D33,1)) -> 0.016170578
A34: =A19 -> 10 | B34: =IF(WEEKDAY(C19)=6,C19+2,IF(WEEKDAY(C19)=7,C19+1,C19)) -> 45939 | C34: =IFERROR(MATCH(B34,Data!$A$2:$A$718,0),MATCH(B34,Data!$A$2:$A$718,-1)) -> 136 | D34: =MIN($B$4,COUNTA(Data!$A:$A)-1-(C34+11)+1) -> 252 | E34: =INTERCEPT(OFFSET(Data!$H$1,C34+11,0,D34,1),OFFSET(Data!$F$1,C34+11,0,D34,1)) -> 0.00058771904 | F34: =SLOPE(OFFSET(Data!$H$1,C34+11,0,D34,1),OFFSET(Data!$F$1,C34+11,0,D34,1)) -> 0.9953579 | H34: =RSQ(OFFSET(Data!$H$1,C34+11,0,D34,1),OFFSET(Data!$F$1,C34+11,0,D34,1)) -> 0.19613103 | I34: =STEYX(OFFSET(Data!$H$1,C34+11,0,D34,1),OFFSET(Data!$F$1,C34+11,0,D34,1)) -> 0.020178646
A35: =A20 -> 11 | B35: =IF(WEEKDAY(C20)=6,C20+2,IF(WEEKDAY(C20)=7,C20+1,C20)) -> 46083 | C35: =IFERROR(MATCH(B35,Data!$A$2:$A$718,0),MATCH(B35,Data!$A$2:$A$718,-1)) -> 37 | D35: =MIN($B$4,COUNTA(Data!$A:$A)-1-(C35+11)+1) -> 252 | E35: =INTERCEPT(OFFSET(Data!$H$1,C35+11,0,D35,1),OFFSET(Data!$F$1,C35+11,0,D35,1)) -> 0.0011984016 | F35: =SLOPE(OFFSET(Data!$H$1,C35+11,0,D35,1),OFFSET(Data!$F$1,C35+11,0,D35,1)) -> 0.82484742 | H35: =RSQ(OFFSET(Data!$H$1,C35+11,0,D35,1),OFFSET(Data!$F$1,C35+11,0,D35,1)) -> 0.13151679 | I35: =STEYX(OFFSET(Data!$H$1,C35+11,0,D35,1),OFFSET(Data!$F$1,C35+11,0,D35,1)) -> 0.023125207
A36: =A21 -> 12 | B36: =IF(WEEKDAY(C21)=6,C21+2,IF(WEEKDAY(C21)=7,C21+1,C21)) -> 46121 | C36: =IFERROR(MATCH(B36,Data!$A$2:$A$718,0),MATCH(B36,Data!$A$2:$A$718,-1)) -> 14 | D36: =MIN($B$4,COUNTA(Data!$A:$A)-1-(C36+11)+1) -> 252 | E36: =INTERCEPT(OFFSET(Data!$H$1,C36+11,0,D36,1),OFFSET(Data!$F$1,C36+11,0,D36,1)) -> 0.00092044387 | F36: =SLOPE(OFFSET(Data!$H$1,C36+11,0,D36,1),OFFSET(Data!$F$1,C36+11,0,D36,1)) -> 0.86729297 | H36: =RSQ(OFFSET(Data!$H$1,C36+11,0,D36,1),OFFSET(Data!$F$1,C36+11,0,D36,1)) -> 0.1489833 | I36: =STEYX(OFFSET(Data!$H$1,C36+11,0,D36,1),OFFSET(Data!$F$1,C36+11,0,D36,1)) -> 0.023560232
A38: Event windows [-10, +10] AR = Actual - Expected; t = AR / sey; CAR = (1+CARprev)(1+AR)-1
A39: Event 1 | B39: =E10 -> Hamas attack; Israel declares war
A40: rel day | B40: weekday | C40: Date | D40: Actual | E40: Expected | F40: AR | G40: t-test | H40: Sig? | I40: CAR | L40: SIG?
A41: 10 | B41: =TEXT(WEEKDAY(C41),"ddd") -> Sun | C41: =OFFSET(Data!$A$1,$C$25-A41,0,1,1) -> 45221 | D41: =_xlfn.XLOOKUP(C41,Data!$A:$A,Data!$H:$H) -> 0.013783702 | E41: =$E$25+$F$25*_xlfn.XLOOKUP(C41,Data!$A:$A,Data!$F:$F) -> -0.0063162717 | F41: =D41-E41 -> 0.020099974 | G41: =F41/$I$25 -> 1.1320481 | H41: =IF(ABS(G41)<$B$6,"No","Yes") -> No | I41: =(1+I42)*(1+F41)-1 -> 0.0074946265
A42: 9 | B42: =TEXT(WEEKDAY(C42),"ddd") -> Thu | C42: =OFFSET(Data!$A$1,$C$25-A42,0,1,1) -> 45218 | D42: =_xlfn.XLOOKUP(C42,Data!$A:$A,Data!$H:$H) -> 0.021823247 | E42: =$E$25+$F$25*_xlfn.XLOOKUP(C42,Data!$A:$A,Data!$F:$F) -> -0.0048320547 | F42: =D42-E42 -> 0.026655302 | G42: =F42/$I$25 -> 1.50125 | H42: =IF(ABS(G42)<$B$6,"No","Yes") -> No | I42: =(1+I43)*(1+F42)-1 -> -0.012356972
A43: 8 | B43: =TEXT(WEEKDAY(C43),"ddd") -> Wed | C43: =OFFSET(Data!$A$1,$C$25-A43,0,1,1) -> 45217 | D43: =_xlfn.XLOOKUP(C43,Data!$A:$A,Data!$H:$H) -> 0.0046649044 | E43: =$E$25+$F$25*_xlfn.XLOOKUP(C43,Data!$A:$A,Data!$F:$F) -> -0.00010032445 | F43: =D43-E43 -> 0.0047652288 | G43: =F43/$I$25 -> 0.26838187 | H43: =IF(ABS(G43)<$B$6,"No","Yes") -> No | I43: =(1+I44)*(1+F43)-1 -> -0.037999389
A44: 7 | B44: =TEXT(WEEKDAY(C44),"ddd") -> Tue | C44: =OFFSET(Data!$A$1,$C$25-A44,0,1,1) -> 45216 | D44: =_xlfn.XLOOKUP(C44,Data!$A:$A,Data!$H:$H) -> 0.017241379 | E44: =$E$25+$F$25*_xlfn.XLOOKUP(C44,Data!$A:$A,Data!$F:$F) -> -0.0020085008 | F44: =D44-E44 -> 0.01924988 | G44: =F44/$I$25 -> 1.0841701 | H44: =IF(ABS(G44)<$B$6,"No","Yes") -> No | I44: =(1+I45)*(1+F44)-1 -> -0.042561801
...

Sheet Dan
A1: Dan — Event Study (market model, single-variable regression)
A3: Parameters
A4: Estimation window (max days) | B4: 252
A5: Event window (days each side) | B5: 10
A6: Significance |t| > | B6: 1.96
A8: Events
A9: # | B9: Event date | C9: TASE t=0 | D9: Sign | E9: Description
A10: 1 | B10: 45206 | C10: =IF(WEEKDAY(B10)=6,B10+2,IF(WEEKDAY(B10)=7,B10+1,B10)) -> 45207 | D10: - | E10: Hamas attack; Israel declares war
A11: 2 | B11: 45252 | C11: =IF(WEEKDAY(B11)=6,B11+2,IF(WEEKDAY(B11)=7,B11+1,B11)) -> 45252 | D11: + | E11: First hostage truce (105 freed)
A12: 3 | B12: 45396 | C12: =IF(WEEKDAY(B12)=6,B12+2,IF(WEEKDAY(B12)=7,B12+1,B12)) -> 45396 | D12: - | E12: Iran first direct attack
A13: 4 | B13: 45504 | C13: =IF(WEEKDAY(B13)=6,B13+2,IF(WEEKDAY(B13)=7,B13+1,B13)) -> 45504 | D13: - | E13: Haniyeh assassinated in Tehran
A14: 5 | B14: 45566 | C14: 45571 | D14: - | E14: Iran second attack (~180 missiles)
A15: 6 | B15: 45623 | C15: =IF(WEEKDAY(B15)=6,B15+2,IF(WEEKDAY(B15)=7,B15+1,B15)) -> 45623 | D15: + | E15: Israel-Lebanon ceasefire
A16: 7 | B16: 45672 | C16: =IF(WEEKDAY(B16)=6,B16+2,IF(WEEKDAY(B16)=7,B16+1,B16)) -> 45672 | D16: + | E16: Gaza ceasefire (33 hostages)
A17: 8 | B17: 45789 | C17: 45789 | D17: + | E17: Edan Alexander released
A18: 9 | B18: 45821 | C18: =IF(WEEKDAY(B18)=6,B18+2,IF(WEEKDAY(B18)=7,B18+1,B18)) -> 45823 | D18: - | E18: 12-Day War begins
A19: 10 | B19: 45939 | C19: =IF(WEEKDAY(B19)=6,B19+2,IF(WEEKDAY(B19)=7,B19+1,B19)) -> 45939 | D19: + | E19: Sharm el-Sheikh deal
A20: 11 | B20: 46081 | C20: =IF(WEEKDAY(B20)=7, B20+2, IF(WEEKDAY(B20)=1, B20+1, B20)) -> 46083 | D20: - | E20: 2026 Israel-Iran war begins
A21: 12 | B21: 46120 | C21: 46121 | D21: + | E21: Pakistan-brokered ceasefire
A23: Model info & statistics — market-model regression (stock daily return on TA-125 daily return; 252-day estimation window). Intercept = α (INTERCEPT), b1 = β (SLOPE), R² (RSQ), sey = standard error of the estimate (STEYX).
A24: # | B24: Event t=0 (adj) | C24: Event point | D24: Window | E24: a (intercept) | F24: b1 (TA125) | G24: (unused) | H24: R2 | I24: sey
A25: =A10 -> 1 | B25: =IF(WEEKDAY(C10)=6,C10+2,IF(WEEKDAY(C10)=7,C10+1,C10)) -> 45207 | C25: =IFERROR(MATCH(B25,Data!$A$2:$A$718,0),MATCH(B25,Data!$A$2:$A$718,-1)) -> 630 | D25: =MIN($B$4,COUNTA(Data!$A:$A)-1-(C25+11)+1) -> 252 | E25: =INTERCEPT(OFFSET(Data!$I$1,C25+11,0,D25,1),OFFSET(Data!$F$1,C25+11,0,D25,1)) -> -0.00049567691 | F25: =SLOPE(OFFSET(Data!$I$1,C25+11,0,D25,1),OFFSET(Data!$F$1,C25+11,0,D25,1)) -> 0.11154208 | H25: =RSQ(OFFSET(Data!$I$1,C25+11,0,D25,1),OFFSET(Data!$F$1,C25+11,0,D25,1)) -> 0.0096801894 | I25: =STEYX(OFFSET(Data!$I$1,C25+11,0,D25,1),OFFSET(Data!$F$1,C25+11,0,D25,1)) -> 0.01176835
A26: =A11 -> 2 | B26: =IF(WEEKDAY(C11)=6,C11+2,IF(WEEKDAY(C11)=7,C11+1,C11)) -> 45252 | C26: =IFERROR(MATCH(B26,Data!$A$2:$A$718,0),MATCH(B26,Data!$A$2:$A$718,-1)) -> 597 | D26: =MIN($B$4,COUNTA(Data!$A:$A)-1-(C26+11)+1) -> 252 | E26: =INTERCEPT(OFFSET(Data!$I$1,C26+11,0,D26,1),OFFSET(Data!$F$1,C26+11,0,D26,1)) -> -0.00073523555 | F26: =SLOPE(OFFSET(Data!$I$1,C26+11,0,D26,1),OFFSET(Data!$F$1,C26+11,0,D26,1)) -> 0.22071894 | H26: =RSQ(OFFSET(Data!$I$1,C26+11,0,D26,1),OFFSET(Data!$F$1,C26+11,0,D26,1)) -> 0.038280323 | I26: =STEYX(OFFSET(Data!$I$1,C26+11,0,D26,1),OFFSET(Data!$F$1,C26+11,0,D26,1)) -> 0.012837469
A27: =A12 -> 3 | B27: =IF(WEEKDAY(C12)=6,C12+2,IF(WEEKDAY(C12)=7,C12+1,C12)) -> 45396 | C27: =IFERROR(MATCH(B27,Data!$A$2:$A$718,0),MATCH(B27,Data!$A$2:$A$718,-1)) -> 497 | D27: =MIN($B$4,COUNTA(Data!$A:$A)-1-(C27+11)+1) -> 252 | E27: =INTERCEPT(OFFSET(Data!$I$1,C27+11,0,D27,1),OFFSET(Data!$F$1,C27+11,0,D27,1)) -> 0.00018098926 | F27: =SLOPE(OFFSET(Data!$I$1,C27+11,0,D27,1),OFFSET(Data!$F$1,C27+11,0,D27,1)) -> 0.23559377 | H27: =RSQ(OFFSET(Data!$I$1,C27+11,0,D27,1),OFFSET(Data!$F$1,C27+11,0,D27,1)) -> 0.033146306 | I27: =STEYX(OFFSET(Data!$I$1,C27+11,0,D27,1),OFFSET(Data!$F$1,C27+11,0,D27,1)) -> 0.013780371
A28: =A13 -> 4 | B28: =IF(WEEKDAY(C13)=6,C13+2,IF(WEEKDAY(C13)=7,C13+1,C13)) -> 45504 | C28: =IFERROR(MATCH(B28,Data!$A$2:$A$718,0),MATCH(B28,Data!$A$2:$A$718,-1)) -> 427 | D28: =MIN($B$4,COUNTA(Data!$A:$A)-1-(C28+11)+1) -> 252 | E28: =INTERCEPT(OFFSET(Data!$I$1,C28+11,0,D28,1),OFFSET(Data!$F$1,C28+11,0,D28,1)) -> -0.00016159767 | F28: =SLOPE(OFFSET(Data!$I$1,C28+11,0,D28,1),OFFSET(Data!$F$1,C28+11,0,D28,1)) -> 0.25415525 | H28: =RSQ(OFFSET(Data!$I$1,C28+11,0,D28,1),OFFSET(Data!$F$1,C28+11,0,D28,1)) -> 0.040837068 | I28: =STEYX(OFFSET(Data!$I$1,C28+11,0,D28,1),OFFSET(Data!$F$1,C28+11,0,D28,1)) -> 0.013440895
A29: =A14 -> 5 | B29: =IF(WEEKDAY(C14)=6,C14+2,IF(WEEKDAY(C14)=7,C14+1,C14)) -> 45571 | C29: =IFERROR(MATCH(B29,Data!$A$2:$A$718,0),MATCH(B29,Data!$A$2:$A$718,-1)) -> 383 | D29: =MIN($B$4,COUNTA(Data!$A:$A)-1-(C29+11)+1) -> 252 | E29: =INTERCEPT(OFFSET(Data!$I$1,C29+11,0,D29,1),OFFSET(Data!$F$1,C29+11,0,D29,1)) -> -3.0717479e-05 | F29: =SLOPE(OFFSET(Data!$I$1,C29+11,0,D29,1),OFFSET(Data!$F$1,C29+11,0,D29,1)) -> 0.18775614 | H29: =RSQ(OFFSET(Data!$I$1,C29+11,0,D29,1),OFFSET(Data!$F$1,C29+11,0,D29,1)) -> 0.025173944 | I29: =STEYX(OFFSET(Data!$I$1,C29+11,0,D29,1),OFFSET(Data!$F$1,C29+11,0,D29,1)) -> 0.012824566
A30: =A15 -> 6 | B30: =IF(WEEKDAY(C15)=6,C15+2,IF(WEEKDAY(C15)=7,C15+1,C15)) -> 45623 | C30: =IFERROR(MATCH(B30,Data!$A$2:$A$718,0),MATCH(B30,Data!$A$2:$A$718,-1)) -> 349 | D30: =MIN($B$4,COUNTA(Data!$A:$A)-1-(C30+11)+1) -> 252 | E30: =INTERCEPT(OFFSET(Data!$I$1,C30+11,0,D30,1),OFFSET(Data!$F$1,C30+11,0,D30,1)) -> 0.00024884628 | F30: =SLOPE(OFFSET(Data!$I$1,C30+11,0,D30,1),OFFSET(Data!$F$1,C30+11,0,D30,1)) -> 0.065817921 | H30: =RSQ(OFFSET(Data!$I$1,C30+11,0,D30,1),OFFSET(Data!$F$1,C30+11,0,D30,1)) -> 0.0028707918 | I30: =STEYX(OFFSET(Data!$I$1,C30+11,0,D30,1),OFFSET(Data!$F$1,C30+11,0,D30,1)) -> 0.011748483
A31: =A16 -> 7 | B31: =IF(WEEKDAY(C16)=6,C16+2,IF(WEEKDAY(C16)=7,C16+1,C16)) -> 45672 | C31: =IFERROR(MATCH(B31,Data!$A$2:$A$718,0),MATCH(B31,Data!$A$2:$A$718,-1)) -> 314 | D31: =MIN($B$4,COUNTA(Data!$A:$A)-1-(C31+11)+1) -> 252 | E31: =INTERCEPT(OFFSET(Data!$I$1,C31+11,0,D31,1),OFFSET(Data!$F$1,C31+11,0,D31,1)) -> 0.000254578 | F31: =SLOPE(OFFSET(Data!$I$1,C31+11,0,D31,1),OFFSET(Data!$F$1,C31+11,0,D31,1)) -> 0.051232162 | H31: =RSQ(OFFSET(Data!$I$1,C31+11,0,D31,1),OFFSET(Data!$F$1,C31+11,0,D31,1)) -> 0.0017758253 | I31: =STEYX(OFFSET(Data!$I$1,C31+11,0,D31,1),OFFSET(Data!$F$1,C31+11,0,D31,1)) -> 0.010941814
A32: =A17 -> 8 | B32: =IF(WEEKDAY(C17)=6,C17+2,IF(WEEKDAY(C17)=7,C17+1,C17)) -> 45789 | C32: =IFERROR(MATCH(B32,Data!$A$2:$A$718,0),MATCH(B32,Data!$A$2:$A$718,-1)) -> 234 | D32: =MIN($B$4,COUNTA(Data!$A:$A)-1-(C32+11)+1) -> 252 | E32: =INTERCEPT(OFFSET(Data!$I$1,C32+11,0,D32,1),OFFSET(Data!$F$1,C32+11,0,D32,1)) -> -0.00015373291 | F32: =SLOPE(OFFSET(Data!$I$1,C32+11,0,D32,1),OFFSET(Data!$F$1,C32+11,0,D32,1)) -> 0.17186973 | H32: =RSQ(OFFSET(Data!$I$1,C32+11,0,D32,1),OFFSET(Data!$F$1,C32+11,0,D32,1)) -> 0.015609395 | I32: =STEYX(OFFSET(Data!$I$1,C32+11,0,D32,1),OFFSET(Data!$F$1,C32+11,0,D32,1)) -> 0.013758419
A33: =A18 -> 9 | B33: =IF(WEEKDAY(C18)=6,C18+2,IF(WEEKDAY(C18)=7,C18+1,C18)) -> 45823 | C33: =IFERROR(MATCH(B33,Data!$A$2:$A$718,0),MATCH(B33,Data!$A$2:$A$718,-1)) -> 212 | D33: =MIN($B$4,COUNTA(Data!$A:$A)-1-(C33+11)+1) -> 252 | E33: =INTERCEPT(OFFSET(Data!$I$1,C33+11,0,D33,1),OFFSET(Data!$F$1,C33+11,0,D33,1)) -> -0.00010009684 | F33: =SLOPE(OFFSET(Data!$I$1,C33+11,0,D33,1),OFFSET(Data!$F$1,C33+11,0,D33,1)) -> 0.19999511 | H33: =RSQ(OFFSET(Data!$I$1,C33+11,0,D33,1),OFFSET(Data!$F$1,C33+11,0,D33,1)) -> 0.018238285 | I33: =STEYX(OFFSET(Data!$I$1,C33+11,0,D33,1),OFFSET(Data!$F$1,C33+11,0,D33,1)) -> 0.014625995
A34: =A19 -> 10 | B34: =IF(WEEKDAY(C19)=6,C19+2,IF(WEEKDAY(C19)=7,C19+1,C19)) -> 45939 | C34: =IFERROR(MATCH(B34,Data!$A$2:$A$718,0),MATCH(B34,Data!$A$2:$A$718,-1)) -> 136 | D34: =MIN($B$4,COUNTA(Data!$A:$A)-1-(C34+11)+1) -> 252 | E34: =INTERCEPT(OFFSET(Data!$I$1,C34+11,0,D34,1),OFFSET(Data!$F$1,C34+11,0,D34,1)) -> -0.00036793553 | F34: =SLOPE(OFFSET(Data!$I$1,C34+11,0,D34,1),OFFSET(Data!$F$1,C34+11,0,D34,1)) -> 0.45472165 | H34: =RSQ(OFFSET(Data!$I$1,C34+11,0,D34,1),OFFSET(Data!$F$1,C34+11,0,D34,1)) -> 0.063291422 | I34: =STEYX(OFFSET(Data!$I$1,C34+11,0,D34,1),OFFSET(Data!$F$1,C34+11,0,D34,1)) -> 0.017517363
A35: =A20 -> 11 | B35: =IF(WEEKDAY(C20)=6,C20+2,IF(WEEKDAY(C20)=7,C20+1,C20)) -> 46083 | C35: =IFERROR(MATCH(B35,Data!$A$2:$A$718,0),MATCH(B35,Data!$A$2:$A$718,-1)) -> 37 | D35: =MIN($B$4,COUNTA(Data!$A:$A)-1-(C35+11)+1) -> 252 | E35: =INTERCEPT(OFFSET(Data!$I$1,C35+11,0,D35,1),OFFSET(Data!$F$1,C35+11,0,D35,1)) -> 0.001105731 | F35: =SLOPE(OFFSET(Data!$I$1,C35+11,0,D35,1),OFFSET(Data!$F$1,C35+11,0,D35,1)) -> 0.43279233 | H35: =RSQ(OFFSET(Data!$I$1,C35+11,0,D35,1),OFFSET(Data!$F$1,C35+11,0,D35,1)) -> 0.062895139 | I35: =STEYX(OFFSET(Data!$I$1,C35+11,0,D35,1),OFFSET(Data!$F$1,C35+11,0,D35,1)) -> 0.018225817
A36: =A21 -> 12 | B36: =IF(WEEKDAY(C21)=6,C21+2,IF(WEEKDAY(C21)=7,C21+1,C21)) -> 46121 | C36: =IFERROR(MATCH(B36,Data!$A$2:$A$718,0),MATCH(B36,Data!$A$2:$A$718,-1)) -> 14 | D36: =MIN($B$4,COUNTA(Data!$A:$A)-1-(C36+11)+1) -> 252 | E36: =INTERCEPT(OFFSET(Data!$I$1,C36+11,0,D36,1),OFFSET(Data!$F$1,C36+11,0,D36,1)) -> 0.00076649658 | F36: =SLOPE(OFFSET(Data!$I$1,C36+11,0,D36,1),OFFSET(Data!$F$1,C36+11,0,D36,1)) -> 0.36440499 | H36: =RSQ(OFFSET(Data!$I$1,C36+11,0,D36,1),OFFSET(Data!$F$1,C36+11,0,D36,1)) -> 0.047214143 | I36: =STEYX(OFFSET(Data!$I$1,C36+11,0,D36,1),OFFSET(Data!$F$1,C36+11,0,D36,1)) -> 0.018606273
A38: Event windows [-10, +10] AR = Actual - Expected; t = AR / sey; CAR = (1+CARprev)(1+AR)-1
A39: Event 1 | B39: =E10 -> Hamas attack; Israel declares war
A40: rel day | B40: weekday | C40: Date | D40: Actual | E40: Expected | F40: AR | G40: t-test | H40: Sig? | I40: CAR | L40: SIG?
A41: 10 | B41: =TEXT(WEEKDAY(C41),"ddd") -> Sun | C41: =OFFSET(Data!$A$1,$C$25-A41,0,1,1) -> 45221 | D41: =_xlfn.XLOOKUP(C41,Data!$A:$A,Data!$I:$I) -> 0.017628911 | E41: =$E$25+$F$25*_xlfn.XLOOKUP(C41,Data!$A:$A,Data!$F:$F) -> -0.0033088709 | F41: =D41-E41 -> 0.020937782 | G41: =F41/$I$25 -> 1.7791605 | H41: =IF(ABS(G41)<$B$6,"No","Yes") -> No | I41: =(1+I42)*(1+F41)-1 -> -0.058397929
A42: 9 | B42: =TEXT(WEEKDAY(C42),"ddd") -> Thu | C42: =OFFSET(Data!$A$1,$C$25-A42,0,1,1) -> 45218 | D42: =_xlfn.XLOOKUP(C42,Data!$A:$A,Data!$I:$I) -> 0 | E42: =$E$25+$F$25*_xlfn.XLOOKUP(C42,Data!$A:$A,Data!$F:$F) -> -0.0024910106 | F42: =D42-E42 -> 0.0024910106 | G42: =F42/$I$25 -> 0.21167034 | H42: =IF(ABS(G42)<$B$6,"No","Yes") -> No | I42: =(1+I43)*(1+F42)-1 -> -0.077708665
A43: 8 | B43: =TEXT(WEEKDAY(C43),"ddd") -> Wed | C43: =OFFSET(Data!$A$1,$C$25-A43,0,1,1) -> 45217 | D43: =_xlfn.XLOOKUP(C43,Data!$A:$A,Data!$I:$I) -> 0 | E43: =$E$25+$F$25*_xlfn.XLOOKUP(C43,Data!$A:$A,Data!$F:$F) -> 0.00011635367 | F43: =D43-E43 -> -0.00011635367 | G43: =F43/$I$25 -> -0.0098869997 | H43: =IF(ABS(G43)<$B$6,"No","Yes") -> No | I43: =(1+I44)*(1+F43)-1 -> -0.080000393
A44: 7 | B44: =TEXT(WEEKDAY(C44),"ddd") -> Tue | C44: =OFFSET(Data!$A$1,$C$25-A44,0,1,1) -> 45216 | D44: =_xlfn.XLOOKUP(C44,Data!$A:$A,Data!$I:$I) -> -0.013478261 | E44: =$E$25+$F$25*_xlfn.XLOOKUP(C44,Data!$A:$A,Data!$F:$F) -> -0.00093512442 | F44: =D44-E44 -> -0.012543136 | G44: =F44/$I$25 -> -1.0658365 | H44: =IF(ABS(G44)<$B$6,"No","Yes") -> No | I44: =(1+I45)*(1+F44)-1 -> -0.079893335
...

Sheet Cross sectional
A1: Date | B1: TA125_Ret | C1: Fattal_Ret | D1: Isrotel_Ret | E1: Dan_Ret | G1: Event Study — Cross-Sectional AAR / CAAR (Security escalation +/- de-escalation) | AS1: Positive group (de-escalation) | BA1: Negative group (escalation)
A2: =Data!A2 -> 46142 | B2: =Data!F2 -> 0.00034319636 | C2: =Data!G2 -> 0.002728513 | D2: =Data!H2 -> -0.00064935065 | E2: =Data!I2 -> -0.041549296 | G2: Event # | H2: 1 | I2: 1 | J2: 1 | K2: 2 | L2: 2 | M2: 2 | N2: 3 | O2: 3 | P2: 3 | Q2: 4 | R2: 4 | S2: 4 | T2: 5 | U2: 5 | V2: 5 | W2: 6 | X2: 6 | Y2: 6 | Z2: 7 | AA2: 7 | AB2: 7 | AC2: 8 | AD2: 8 | AE2: 8 | AF2: 9 | AG2: 9 | AH2: 9 | AI2: 10 | AJ2: 10 | AK2: 10 | AL2: 11 | AM2: 11 | AN2: 11 | AO2: 12 | AP2: 12 | AQ2: 12 | AS2: rel day | AT2: AAR | AU2: cross-sec SE | AV2: t-stat | AW2: Sig? | AX2: CAAR | AY2: n | BA2: rel day | BB2: AAR | BC2: cross-sec SE | BD2: t-stat | BE2: Sig? | BF2: CAAR | BG2: n
A3: =Data!A3 -> 46141 | B3: =Data!F3 -> 0.012818766 | C3: =Data!G3 -> 0.0013661202 | D3: =Data!H3 -> 0 | E3: =Data!I3 -> -0.010452962 | G3: t=0 | H3: =Fattal!B25 -> 45207 | I3: =Isrotel!B25 -> 45207 | J3: =Dan!B25 -> 45207 | K3: =Fattal!B26 -> 45252 | L3: =Isrotel!B26 -> 45252 | M3: =Dan!B26 -> 45252 | N3: =Fattal!B27 -> 45396 | O3: =Isrotel!B27 -> 45396 | P3: =Dan!B27 -> 45396 | Q3: =Fattal!B28 -> 45504 | R3: =Isrotel!B28 -> 45504 | S3: =Dan!B28 -> 45504 | T3: =Fattal!B29 -> 45571 | U3: =Isrotel!B29 -> 45571 | V3: =Dan!B29 -> 45571 | W3: =Fattal!B30 -> 45623 | X3: =Isrotel!B30 -> 45623 | Y3: =Dan!B30 -> 45623 | Z3: =Fattal!B31 -> 45672 | AA3: =Isrotel!B31 -> 45672 | AB3: =Dan!B31 -> 45672 | AC3: =Fattal!B32 -> 45789 | AD3: =Isrotel!B32 -> 45789 | AE3: =Dan!B32 -> 45789 | AF3: =Fattal!B33 -> 45823 | AG3: =Isrotel!B33 -> 45823 | AH3: =Dan!B33 -> 45823 | AI3: =Fattal!B34 -> 45939 | AJ3: =Isrotel!B34 -> 45939 | AK3: =Dan!B34 -> 45939 | AL3: =Fattal!B35 -> 46083 | AM3: =Isrotel!B35 -> 46083 | AN3: =Dan!B35 -> 46083 | AO3: =Fattal!B36 -> 46121 | AP3: =Isrotel!B36 -> 46121 | AQ3: =Dan!B36 -> 46121 | AS3: 10 | AT3: =AVERAGEIF($H$5:$AQ$5,"+",$H13:$AQ13) -> 0.0072230143 | AU3: {=SQRT(SUMPRODUCT(($H$5:$AQ$5="+")*($H13:$AQ13-AT3)^2)/(AY3-1))/SQRT(AY3)} -> 0.0032188252 | AV3: =AT3/AU3 -> 2.2439909 | AW3: =IF(ABS(AV3)<1.96,"No","Yes") -> Yes | AX3: =(1+AX4)*(1+AT3)-1 -> 0.027065876 | AY3: =COUNTIF($H$5:$AQ$5,"+") -> 18 | BA3: 10 | BB3: =AVERAGEIF($H$5:$AQ$5,"-",$H13:$AQ13) -> 0.0033846766 | BC3: {=SQRT(SUMPRODUCT(($H$5:$AQ$5="-")*($H13:$AQ13-BB3)^2)/(BG3-1))/SQRT(BG3)} -> 0.0043448473 | BD3: =BB3/BC3 -> 0.77900933 | BE3: =IF(ABS(BD3)<1.96,"No","Yes") -> No | BF3: =(1+BF4)*(1+BB3)-1 -> -0.017506627 | BG3: =COUNTIF($H$5:$AQ$5,"-") -> 18
A4: =Data!A4 -> 46140 | B4: =Data!F4 -> -0.0031139373 | C4: =Data!G4 -> -0.003403676 | D4: =Data!H4 -> -0.012820513 | E4: =Data!I4 -> -0.010344828 | G4: Stock | H4: Fattal | I4: Isrotel | J4: Dan | K4: Fattal | L4: Isrotel | M4: Dan | N4: Fattal | O4: Isrotel | P4: Dan | Q4: Fattal | R4: Isrotel | S4: Dan | T4: Fattal | U4: Isrotel | V4: Dan | W4: Fattal | X4: Isrotel | Y4: Dan | Z4: Fattal | AA4: Isrotel | AB4: Dan | AC4: Fattal | AD4: Isrotel | AE4: Dan | AF4: Fattal | AG4: Isrotel | AH4: Dan | AI4: Fattal | AJ4: Isrotel | AK4: Dan | AL4: Fattal | AM4: Isrotel | AN4: Dan | AO4: Fattal | AP4: Isrotel | AQ4: Dan | AS4: 9 | AT4: =AVERAGEIF($H$5:$AQ$5,"+",$H14:$AQ14) -> 0.001577965 | AU4: {=SQRT(SUMPRODUCT(($H$5:$AQ$5="+")*($H14:$AQ14-AT4)^2)/(AY4-1))/SQRT(AY4)} -> 0.0047197801 | AV4: =AT4/AU4 -> 0.33433018 | AW4: =IF(ABS(AV4)<1.96,"No","Yes") -> No | AX4: =(1+AX5)*(1+AT4)-1 -> 0.019700565 | AY4: =COUNTIF($H$5:$AQ$5,"+") -> 18 | BA4: 9 | BB4: =AVERAGEIF($H$5:$AQ$5,"-",$H14:$AQ14) -> -0.00026333133 | BC4: {=SQRT(SUMPRODUCT(($H$5:$AQ$5="-")*($H14:$AQ14-BB4)^2)/(BG4-1))/SQRT(BG4)} -> 0.0039345219 | BD4: =BB4/BC4 -> -0.066928418 | BE4: =IF(ABS(BD4)<1.96,"No","Yes") -> No | BF4: =(1+BF5)*(1+BB4)-1 -> -0.020820832 | BG4: =COUNTIF($H$5:$AQ$5,"-") -> 18
A5: =Data!A5 -> 46139 | B5: =Data!F5 -> -0.00080242365 | C5: =Data!G5 -> 0.035236082 | D5: =Data!H5 -> 0.011017498 | E5: =Data!I5 -> 0 | G5: Sign | H5: - | I5: - | J5: - | K5: + | L5: + | M5: + | N5: - | O5: - | P5: - | Q5: - | R5: - | S5: - | T5: - | U5: - | V5: - | W5: + | X5: + | Y5: + | Z5: + | AA5: + | AB5: + | AC5: + | AD5: + | AE5: + | AF5: - | AG5: - | AH5: - | AI5: + | AJ5: + | AK5: + | AL5: - | AM5: - | AN5: - | AO5: + | AP5: + | AQ5: + | AS5: 8 | AT5: =AVERAGEIF($H$5:$AQ$5,"+",$H15:$AQ15) -> 0.0062425793 | AU5: {=SQRT(SUMPRODUCT(($H$5:$AQ$5="+")*($H15:$AQ15-AT5)^2)/(AY5-1))/SQRT(AY5)} -> 0.0030801467 | AV5: =AT5/AU5 -> 2.026715 | AW5: =IF(ABS(AV5)<1.96,"No","Yes") -> Yes | AX5: =(1+AX6)*(1+AT5)-1 -> 0.018094048 | AY5: =COUNTIF($H$5:$AQ$5,"+") -> 18 | BA5: 8 | BB5: =AVERAGEIF($H$5:$AQ$5,"-",$H15:$AQ15) -> 0.0048856839 | BC5: {=SQRT(SUMPRODUCT(($H$5:$AQ$5="-")*($H15:$AQ15-BB5)^2)/(BG5-1))/SQRT(BG5)} -> 0.004519707 | BD5: =BB5/BC5 -> 1.0809736 | BE5: =IF(ABS(BD5)<1.96,"No","Yes") -> No | BF5: =(1+BF6)*(1+BB5)-1 -> -0.020562915 | BG5: =COUNTIF($H$5:$AQ$5,"-") -> 18
A6: =Data!A6 -> 46136 | B6: =Data!F6 -> -0.012361225 | C6: =Data!G6 -> -0.010460251 | D6: =Data!H6 -> -0.019071837 | E6: =Data!I6 -> 0.0017271157 | AS6: 7 | AT6: =AVERAGEIF($H$5:$AQ$5,"+",$H16:$AQ16) -> -0.00087016891 | AU6: {=SQRT(SUMPRODUCT(($H$5:$AQ$5="+")*($H16:$AQ16-AT6)^2)/(AY6-1))/SQRT(AY6)} -> 0.0033700091 | AV6: =AT6/AU6 -> -0.25820966 | AW6: =IF(ABS(AV6)<1.96,"No","Yes") -> No | AX6: =(1+AX7)*(1+AT6)-1 -> 0.011777944 | AY6: =COUNTIF($H$5:$AQ$5,"+") -> 18 | BA6: 7 | BB6: =AVERAGEIF($H$5:$AQ$5,"-",$H16:$AQ16) -> 0.0033629404 | BC6: {=SQRT(SUMPRODUCT(($H$5:$AQ$5="-")*($H16:$AQ16-BB6)^2)/(BG6-1))/SQRT(BG6)} -> 0.0058829281 | BD6: =BB6/BC6 -> 0.57164398 | BE6: =IF(ABS(BD6)<1.96,"No","Yes") -> No | BF6: =(1+BF7)*(1+BB6)-1 -> -0.02532487 | BG6: =COUNTIF($H$5:$AQ$5,"-") -> 18
A7: =Data!A7 -> 46135 | B7: =Data!F7 -> 4.1590898e-05 | C7: =Data!G7 -> 0.019914651 | D7: =Data!H7 -> -0.0069444444 | E7: =Data!I7 -> -0.00069036935 | G7: Event point | H7: =Fattal!C25 -> 630 | I7: =Isrotel!C25 -> 630 | J7: =Dan!C25 -> 630 | K7: =Fattal!C26 -> 597 | L7: =Isrotel!C26 -> 597 | M7: =Dan!C26 -> 597 | N7: =Fattal!C27 -> 497 | O7: =Isrotel!C27 -> 497 | P7: =Dan!C27 -> 497 | Q7: =Fattal!C28 -> 427 | R7: =Isrotel!C28 -> 427 | S7: =Dan!C28 -> 427 | T7: =Fattal!C29 -> 383 | U7: =Isrotel!C29 -> 383 | V7: =Dan!C29 -> 383 | W7: =Fattal!C30 -> 349 | X7: =Isrotel!C30 -> 349 | Y7: =Dan!C30 -> 349 | Z7: =Fattal!C31 -> 314 | AA7: =Isrotel!C31 -> 314 | AB7: =Dan!C31 -> 314 | AC7: =Fattal!C32 -> 234 | AD7: =Isrotel!C32 -> 234 | AE7: =Dan!C32 -> 234 | AF7: =Fattal!C33 -> 212 | AG7: =Isrotel!C33 -> 212 | AH7: =Dan!C33 -> 212 | AI7: =Fattal!C34 -> 136 | AJ7: =Isrotel!C34 -> 136 | AK7: =Dan!C34 -> 136 | AL7: =Fattal!C35 -> 37 | AM7: =Isrotel!C35 -> 37 | AN7: =Dan!C35 -> 37 | AO7: =Fattal!C36 -> 14 | AP7: =Isrotel!C36 -> 14 | AQ7: =Dan!C36 -> 14 | AS7: 6 | AT7: =AVERAGEIF($H$5:$AQ$5,"+",$H17:$AQ17) -> -0.00063592463 | AU7: {=SQRT(SUMPRODUCT(($H$5:$AQ$5="+")*($H17:$AQ17-AT7)^2)/(AY7-1))/SQRT(AY7)} -> 0.0052787131 | AV7: =AT7/AU7 -> -0.12046963 | AW7: =IF(ABS(AV7)<1.96,"No","Yes") -> No | AX7: =(1+AX8)*(1+AT7)-1 -> 0.012659128 | AY7: =COUNTIF($H$5:$AQ$5,"+") -> 18 | BA7: 6 | BB7: =AVERAGEIF($H$5:$AQ$5,"-",$H17:$AQ17) -> -0.0043954893 | BC7: {=SQRT(SUMPRODUCT(($H$5:$AQ$5="-")*($H17:$AQ17-BB7)^2)/(BG7-1))/SQRT(BG7)} -> 0.0045213276 | BD7: =BB7/BC7 -> -0.97216782 | BE7: =IF(ABS(BD7)<1.96,"No","Yes") -> No | BF7: =(1+BF8)*(1+BB7)-1 -> -0.028591658 | BG7: =COUNTIF($H$5:$AQ$5,"-") -> 18
A8: =Data!A8 -> 46132 | B8: =Data!F8 -> 0.0043722137 | C8: =Data!G8 -> 0.0129683 | D8: =Data!H8 -> 0.010204082 | E8: =Data!I8 -> 0 | G8: a | H8: =Fattal!E25 -> 0.00028642491 | I8: =Isrotel!E25 -> -0.0012110107 | J8: =Dan!E25 -> -0.00049567691 | K8: =Fattal!E26 -> 0.0011347158 | L8: =Isrotel!E26 -> -0.00098359429 | M8: =Dan!E26 -> -0.00073523555 | N8: =Fattal!E27 -> 0.0011870735 | O8: =Isrotel!E27 -> 0.00067932195 | P8: =Dan!E27 -> 0.00018098926 | Q8: =Fattal!E28 -> 1.2483265e-05 | R8: =Isrotel!E28 -> 5.7920211e-05 | S8: =Dan!E28 -> -0.00016159767 | T8: =Fattal!E29 -> 0.00015708143 | U8: =Isrotel!E29 -> -7.0571051e-05 | V8: =Dan!E29 -> -3.0717479e-05 | W8: =Fattal!E30 -> -0.00014222531 | X8: =Isrotel!E30 -> -0.00015956978 | Y8: =Dan!E30 -> 0.00024884628 | Z8: =Fattal!E31 -> -0.00019690886 | AA8: =Isrotel!E31 -> 0.00018442855 | AB8: =Dan!E31 -> 0.000254578 | AC8: =Fattal!E32 -> -0.0007467555 | AD8: =Isrotel!E32 -> -0.001197695 | AE8: =Dan!E32 -> -0.00015373291 | AF8: =Fattal!E33 -> -0.0003824267 | AG8: =Isrotel!E33 -> -0.00087320992 | AH8: =Dan!E33 -> -0.00010009684 | AI8: =Fattal!E34 -> -0.00082260592 | AJ8: =Isrotel!E34 -> 0.00058771904 | AK8: =Dan!E34 -> -0.00036793553 | AL8: =Fattal!E35 -> -0.00099985744 | AM8: =Isrotel!E35 -> 0.0011984016 | AN8: =Dan!E35 -> 0.001105731 | AO8: =Fattal!E36 -> -0.00096423103 | AP8: =Isrotel!E36 -> 0.00092044387 | AQ8: =Dan!E36 -> 0.00076649658 | AS8: 5 | AT8: =AVERAGEIF($H$5:$AQ$5,"+",$H18:$AQ18) -> -0.00066526432 | AU8: {=SQRT(SUMPRODUCT(($H$5:$AQ$5="+")*($H18:$AQ18-AT8)^2)/(AY8-1))/SQRT(AY8)} -> 0.0041219062 | AV8: =AT8/AU8 -> -0.16139725 | AW8: =IF(ABS(AV8)<1.96,"No","Yes") -> No | AX8: =(1+AX9)*(1+AT8)-1 -> 0.013303513 | AY8: =COUNTIF($H$5:$AQ$5,"+") -> 18 | BA8: 5 | BB8: =AVERAGEIF($H$5:$AQ$5,"-",$H18:$AQ18) -> 0.0004999882 | BC8: {=SQRT(SUMPRODUCT(($H$5:$AQ$5="-")*($H18:$AQ18-BB8)^2)/(BG8-1))/SQRT(BG8)} -> 0.0027146463 | BD8: =BB8/BC8 -> 0.18418171 | BE8: =IF(ABS(BD8)<1.96,"No","Yes") -> No | BF8: =(1+BF9)*(1+BB8)-1 -> -0.024302992 | BG8: =COUNTIF($H$5:$AQ$5,"-") -> 18
A9: =Data!A9 -> 46129 | B9: =Data!F9 -> 0.010591317 | C9: =Data!G9 -> 0.032738095 | D9: =Data!H9 -> 0.042553191 | E9: =Data!I9 -> 0.0052047189 | G9: b1 | H9: =Fattal!F25 -> 1.4028615 | I9: =Isrotel!F25 -> 0.20242167 | J9: =Dan!F25 -> 0.11154208 | K9: =Fattal!F26 -> 1.3515287 | L9: =Isrotel!F26 -> 0.32767133 | M9: =Dan!F26 -> 0.22071894 | N9: =Fattal!F27 -> 1.1217334 | O9: =Isrotel!F27 -> 0.43617163 | P9: =Dan!F27 -> 0.23559377 | Q9: =Fattal!F28 -> 1.1850264 | R9: =Isrotel!F28 -> 0.52546814 | S9: =Dan!F28 -> 0.25415525 | T9: =Fattal!F29 -> 1.2128881 | U9: =Isrotel!F29 -> 0.67927325 | V9: =Dan!F29 -> 0.18775614 | W9: =Fattal!F30 -> 1.2857621 | X9: =Isrotel!F30 -> 0.73853276 | Y9: =Dan!F30 -> 0.065817921 | Z9: =Fattal!F31 -> 1.2085727 | AA9: =Isrotel!F31 -> 0.73870749 | AB9: =Dan!F31 -> 0.051232162 | AC9: =Fattal!F32 -> 1.112002 | AD9: =Isrotel!F32 -> 0.80039724 | AE9: =Dan!F32 -> 0.17186973 | AF9: =Fattal!F33 -> 1.1191461 | AG9: =Isrotel!F33 -> 0.87301138 | AH9: =Dan!F33 -> 0.19999511 | AI9: =Fattal!F34 -> 1.0944115 | AJ9: =Isrotel!F34 -> 0.9953579 | AK9: =Dan!F34 -> 0.45472165 | AL9: =Fattal!F35 -> 1.0400682 | AM9: =Isrotel!F35 -> 0.82484742 | AN9: =Dan!F35 -> 0.43279233 | AO9: =Fattal!F36 -> 1.0115585 | AP9: =Isrotel!F36 -> 0.86729297 | AQ9: =Dan!F36 -> 0.36440499 | AS9: 4 | AT9: =AVERAGEIF($H$5:$AQ$5,"+",$H19:$AQ19) -> 0.0067027674 | AU9: {=SQRT(SUMPRODUCT(($H$5:$AQ$5="+")*($H19:$AQ19-AT9)^2)/(AY9-1))/SQRT(AY9)} -> 0.0042128738 | AV9: =AT9/AU9 -> 1.5910202 | AW9: =IF(ABS(AV9)<1.96,"No","Yes") -> No | AX9: =(1+AX10)*(1+AT9)-1 -> 0.013978076 | AY9: =COUNTIF($H$5:$AQ$5,"+") -> 18 | BA9: 4 | BB9: =AVERAGEIF($H$5:$AQ$5,"-",$H19:$AQ19) -> -0.0019703497 | BC9: {=SQRT(SUMPRODUCT(($H$5:$AQ$5="-")*($H19:$AQ19-BB9)^2)/(BG9-1))/SQRT(BG9)} -> 0.0040259556 | BD9: =BB9/BC9 -> -0.48941169 | BE9: =IF(ABS(BD9)<1.96,"No","Yes") -> No | BF9: =(1+BF10)*(1+BB9)-1 -> -0.024790586 | BG9: =COUNTIF($H$5:$AQ$5,"-") -> 18
A10: =Data!A10 -> 46128 | B10: =Data!F10 -> -0.010895788 | C10: =Data!G10 -> -0.0098718138 | D10: =Data!H10 -> -0.025906736 | E10: =Data!I10 -> -0.042524917 | G10: sey | H10: =Fattal!I25 -> 0.018253549 | I10: =Isrotel!I25 -> 0.017755405 | J10: =Dan!I25 -> 0.01176835 | K10: =Fattal!I26 -> 0.017779338 | L10: =Isrotel!I26 -> 0.018130911 | M10: =Dan!I26 -> 0.012837469 | N10: =Fattal!I27 -> 0.015674184 | O10: =Isrotel!I27 -> 0.018851355 | P10: =Dan!I27 -> 0.013780371 | Q10: =Fattal!I28 -> 0.014435731 | R10: =Isrotel!I28 -> 0.015338251 | S10: =Dan!I28 -> 0.013440895 | T10: =Fattal!I29 -> 0.014684599 | U10: =Isrotel!I29 -> 0.016012595 | V10: =Dan!I29 -> 0.012824566 | W10: =Fattal!I30 -> 0.014930032 | X10: =Isrotel!I30 -> 0.015991545 | Y10: =Dan!I30 -> 0.011748483 | Z10: =Fattal!I31 -> 0.014935076 | AA10: =Isrotel!I31 -> 0.01617478 | AB10: =Dan!I31 -> 0.010941814 | AC10: =Fattal!I32 -> 0.016032163 | AD10: =Isrotel!I32 -> 0.015805794 | AE10: =Dan!I32 -> 0.013758419 | AF10: =Fattal!I33 -> 0.015880047 | AG10: =Isrotel!I33 -> 0.016170578 | AH10: =Dan!I33 -> 0.014625995 | AI10: =Fattal!I34 -> 0.015956258 | AJ10: =Isrotel!I34 -> 0.020178646 | AK10: =Dan!I34 -> 0.017517363 | AL10: =Fattal!I35 -> 0.015699861 | AM10: =Isrotel!I35 -> 0.023125207 | AN10: =Dan!I35 -> 0.018225817 | AO10: =Fattal!I36 -> 0.016206939 | AP10: =Isrotel!I36 -> 0.023560232 | AQ10: =Dan!I36 -> 0.018606273 | AS10: 3 | AT10: =AVERAGEIF($H$5:$AQ$5,"+",$H20:$AQ20) -> 0.0051279991 | AU10: {=SQRT(SUMPRODUCT(($H$5:$AQ$5="+")*($H20:$AQ20-AT10)^2)/(AY10-1))/SQRT(AY10)} -> 0.0044317174 | AV10: =AT10/AU10 -> 1.1571133 | AW10: =IF(ABS(AV10)<1.96,"No","Yes") -> No | AX10: =(1+AX11)*(1+AT10)-1 -> 0.0072268689 | AY10: =COUNTIF($H$5:$AQ$5,"+") -> 18 | BA10: 3 | BB10: =AVERAGEIF($H$5:$AQ$5,"-",$H20:$AQ20) -> -0.006693558 | BC10: {=SQRT(SUMPRODUCT(($H$5:$AQ$5="-")*($H20:$AQ20-BB10)^2)/(BG10-1))/SQRT(BG10)} -> 0.0034880449 | BD10: =BB10/BC10 -> -1.919 | BE10: =IF(ABS(BD10)<1.96,"No","Yes") -> No | BF10: =(1+BF11)*(1+BB10)-1 -> -0.022865289 | BG10: =COUNTIF($H$5:$AQ$5,"-") -> 18
A11: =Data!A11 -> 46127 | B11: =Data!F11 -> -0.0055915923 | C11: =Data!G11 -> 0.029893778 | D11: =Data!H11 -> -0.01025641 | E11: =Data!I11 -> 0 | AS11: 2 | AT11: =AVERAGEIF($H$5:$AQ$5,"+",$H21:$AQ21) -> -0.0023146533 | AU11: {=SQRT(SUMPRODUCT(($H$5:$AQ$5="+")*($H21:$AQ21-AT11)^2)/(AY11-1))/SQRT(AY11)} -> 0.0053320912 | AV11: =AT11/AU11 -> -0.4340986 | AW11: =IF(ABS(AV11)<1.96,"No","Yes") -> No | AX11: =(1+AX12)*(1+AT11)-1 -> 0.0020881617 | AY11: =COUNTIF($H$5:$AQ$5,"+") -> 18 | BA11: 2 | BB11: =AVERAGEIF($H$5:$AQ$5,"-",$H21:$AQ21) -> 0.0034676115 | BC11: {=SQRT(SUMPRODUCT(($H$5:$AQ$5="-")*($H21:$AQ21-BB11)^2)/(BG11-1))/SQRT(BG11)} -> 0.0052854183 | BD11: =BB11/BC11 -> 0.65607134 | BE11: =IF(ABS(BD11)<1.96,"No","Yes") -> No | BF11: =(1+BF12)*(1+BB11)-1 -> -0.016280706 | BG11: =COUNTIF($H$5:$AQ$5,"-") -> 18
A12: =Data!A12 -> 46126 | B12: =Data!F12 -> 0.014518937 | C12: =Data!G12 -> 0.057784912 | D12: =Data!H12 -> 0.019607843 | E12: =Data!I12 -> 0 | G12: rel \ AR | AS12: 1 | AT12: =AVERAGEIF($H$5:$AQ$5,"+",$H22:$AQ22) -> -0.00011551274 | AU12: {=SQRT(SUMPRODUCT(($H$5:$AQ$5="+")*($H22:$AQ22-AT12)^2)/(AY12-1))/SQRT(AY12)} -> 0.0043037627 | AV12: =AT12/AU12 -> -0.026839943 | AW12: =IF(ABS(AV12)<1.96,"No","Yes") -> No | AX12: =(1+AX13)*(1+AT12)-1 -> 0.0044130297 | AY12: =COUNTIF($H$5:$AQ$5,"+") -> 18 | BA12: 1 | BB12: =AVERAGEIF($H$5:$AQ$5,"-",$H22:$AQ22) -> -0.0024080626 | BC12: {=SQRT(SUMPRODUCT(($H$5:$AQ$5="-")*($H22:$AQ22-BB12)^2)/(BG12-1))/SQRT(BG12)} -> 0.0046583957 | BD12: =BB12/BC12 -> -0.51692961 | BE12: =IF(ABS(BD12)<1.96,"No","Yes") -> No | BF12: =(1+BF13)*(1+BB12)-1 -> -0.019680075 | BG12: =COUNTIF($H$5:$AQ$5,"-") -> 18
A13: =Data!A13 -> 46125 | B13: =Data!F13 -> -0.014456653 | C13: =Data!G13 -> -0.017040076 | D13: =Data!H13 -> -0.0097087379 | E13: =Data!I13 -> 0 | G13: 10 | H13: =_xlfn.XLOOKUP(OFFSET(Data!$A$1,H$7-$G13,0,1,1),Data!$A:$A,Data!$G:$G)-(H$8+H$9*_xlfn.XLOOKUP(OFFSET(Data!$A$1,H$7-$G13,0,1,1),Data!$A:$A,Data!$F:$F)) -> 0.021362201 | I13: =_xlfn.XLOOKUP(OFFSET(Data!$A$1,I$7-$G13,0,1,1),Data!$A:$A,Data!$H:$H)-(I$8+I$9*_xlfn.XLOOKUP(OFFSET(Data!$A$1,I$7-$G13,0,1,1),Data!$A:$A,Data!$F:$F)) -> 0.020099974 | J13: =_xlfn.XLOOKUP(OFFSET(Data!$A$1,J$7-$G13,0,1,1),Data!$A:$A,Data!$I:$I)-(J$8+J$9*_xlfn.XLOOKUP(OFFSET(Data!$A$1,J$7-$G13,0,1,1),Data!$A:$A,Data!$F:$F)) -> 0.020937782 | K13: =_xlfn.XLOOKUP(OFFSET(Data!$A$1,K$7-$G13,0,1,1),Data!$A:$A,Data!$G:$G)-(K$8+K$9*_xlfn.XLOOKUP(OFFSET(Data!$A$1,K$7-$G13,0,1,1),Data!$A:$A,Data!$F:$F)) -> 0.035419888 | L13: =_xlfn.XLOOKUP(OFFSET(Data!$A$1,L$7-$G13,0,1,1),Data!$A:$A,Data!$H:$H)-(L$8+L$9*_xlfn.XLOOKUP(OFFSET(Data!$A$1,L$7-$G13,0,1,1),Data!$A:$A,Data!$F:$F)) -> 0.011402918 | M13: =_xlfn.XLOOKUP(OFFSET(Data!$A$1,M$7-$G13,0,1,1),Data!$A:$A,Data!$I:$I)-(M$8+M$9*_xlfn.XLOOKUP(OFFSET(Data!$A$1,M$7-$G13,0,1,1),Data!$A:$A,Data!$F:$F)) -> -0.011172047 | N13: =_xlfn.XLOOKUP(OFFSET(Data!$A$1,N$7-$G13,0,1,1),Data!$A:$A,Data!$G:$G)-(N$8+N$9*_xlfn.XLOOKUP(OFFSET(Data!$A$1,N$7-$G13,0,1,1),Data!$A:$A,Data!$F:$F)) -> -0.0050592739 | O13: =_xlfn.XLOOKUP(OFFSET(Data!$A$1,O$7-$G13,0,1,1),Data!$A:$A,Data!$H:$H)-(O$8+O$9*_xlfn.XLOOKUP(OFFSET(Data!$A$1,O$7-$G13,0,1,1),Data!$A:$A,Data!$F:$F)) -> -0.031296375 | P13: =_xlfn.XLOOKUP(OFFSET(Data!$A$1,P$7-$G13,0,1,1),Data!$A:$A,Data!$I:$I)-(P$8+P$9*_xlfn.XLOOKUP(OFFSET(Data!$A$1,P$7-$G13,0,1,1),Data!$A:$A,Data!$F:$F)) -> -0.00099425403 | Q13: =_xlfn.XLOOKUP(OFFSET(Data!$A$1,Q$7-$G13,0,1,1),Data!$A:$A,Data!$G:$G)-(Q$8+Q$9*_xlfn.XLOOKUP(OFFSET(Data!$A$1,Q$7-$G13,0,1,1),Data!$A:$A,Data!$F:$F)) -> 0.014101419 | R13: =_xlfn.XLOOKUP(OFFSET(Data!$A$1,R$7-$G13,0,1,1),Data!$A:$A,Data!$H:$H)-(R$8+R$9*_xlfn.XLOOKUP(OFFSET(Data!$A$1,R$7-$G13,0,1,1),Data!$A:$A,Data!$F:$F)) -> 0.026036276 | S13: =_xlfn.XLOOKUP(OFFSET(Data!$A$1,S$7-$G13,0,1,1),Data!$A:$A,Data!$I:$I)-(S$8+S$9*_xlfn.XLOOKUP(OFFSET(Data!$A$1,S$7-$G13,0,1,1),Data!$A:$A,Data!$F:$F)) -> -0.0038015682 | T13: =_xlfn.XLOOKUP(OFFSET(Data!$A$1,T$7-$G13,0,1,1),Data!$A:$A,Data!$G:$G)-(T$8+T$9*_xlfn.XLOOKUP(OFFSET(Data!$A$1,T$7-$G13,0,1,1),Data!$A:$A,Data!$F:$F)) -> -0.019602406 | U13: =_xlfn.XLOOKUP(OFFSET(Data!$A$1,U$7-$G13,0,1,1),Data!$A:$A,Data!$H:$H)-(U$8+U$9*_xlfn.XLOOKUP(OFFSET(Data!$A$1,U$7-$G13,0,1,1),Data!$A:$A,Data!$F:$F)) -> -8.2162472e-05 | V13: =_xlfn.XLOOKUP(OFFSET(Data!$A$1,V$7-$G13,0,1,1),Data!$A:$A,Data!$I:$I)-(V$8+V$9*_xlfn.XLOOKUP(OFFSET(Data!$A$1,V$7-$G13,0,1,1),Data!$A:$A,Data!$F:$F)) -> 0.0017005905 | W13: =_xlfn.XLOOKUP(OFFSET(Data!$A$1,W$7-$G13,0,1,1),Data!$A:$A,Data!$G:$G)-(W$8+W$9*_xlfn.XLOOKUP(OFFSET(Data!$A$1,W$7-$G13,0,1,1),Data!$A:$A,Data!$F:$F)) -> 0.0032577238 | X13: =_xlfn.XLOOKUP(OFFSET(Data!$A$1,X$7-$G13,0,1,1),Data!$A:$A,Data!$H:$H)-(X$8+X$9*_xlfn.XLOOKUP(OFFSET(Data!$A$1,X$7-$G13,0,1,1),Data!$A:$A,Data!$F:$F)) -> -0.0055295376 | Y13: =_xlfn.XLOOKUP(OFFSET(Data!$A$1,Y$7-$G13,0,1,1),Data!$A:$A,Data!$I:$I)-(Y$8+Y$9*_xlfn.XLOOKUP(OFFSET(Data!$A$1,Y$7-$G13,0,1,1),Data!$A:$A,Data!$F:$F)) -> -0.014369077 | Z13: =_xlfn.XLOOKUP(OFFSET(Data!$A$1,Z$7-$G13,0,1,1),Data!$A:$A,Data!$G:$G)-(Z$8+Z$9*_xlfn.XLOOKUP(OFFSET(Data!$A$1,Z$7-$G13,0,1,1),Data!$A:$A,Data!$F:$F)) -> 0.017073229 | AA13: =_xlfn.XLOOKUP(OFFSET(Data!$A$1,AA$7-$G13,0,1,1),Data!$A:$A,Data!$H:$H)-(AA$8+AA$9*_xlfn.XLOOKUP(OFFSET(Data!$A$1,AA$7-$G13,0,1,1),Data!$A:$A,Data!$F:$F)) -> 0.010951561 | AB13: =_xlfn.XLOOKUP(OFFSET(Data!$A$1,AB$7-$G13,0,1,1),Data!$A:$A,Data!$I:$I)-(AB$8+AB$9*_xlfn.XLOOKUP(OFFSET(Data!$A$1,AB$7-$G13,0,1,1),Data!$A:$A,Data!$F:$F)) -> -0.00052461366 | AC13: =_xlfn.XLOOKUP(OFFSET(Data!$A$1,AC$7-$G13,0,1,1),Data!$A:$A,Data!$G:$G)-(AC$8+AC$9*_xlfn.XLOOKUP(OFFSET(Data!$A$1,AC$7-$G13,0,1,1),Data!$A:$A,Data!$F:$F)) -> 0.0028782866 | AD13: =_xlfn.XLOOKUP(OFFSET(Data!$A$1,AD$7-$G13,0,1,1),Data!$A:$A,Data!$H:$H)-(AD$8+AD$9*_xlfn.XLOOKUP(OFFSET(Data!$A$1,AD$7-$G13,0,1,1),Data!$A:$A,Data!$F:$F)) -> 0.011941121 | AE13: =_xlfn.XLOOKUP(OFFSET(Data!$A$1,AE$7-$G13,0,1,1),Data!$A:$A,Data!$I:$I)-(AE$8+AE$9*_xlfn.XLOOKUP(OFFSET(Data!$A$1,AE$7-$G13,0,1,1),Data!$A:$A,Data!$F:$F)) -> 0.012083954 | AF13: =_xlfn.XLOOKUP(OFFSET(Data!$A$1,AF$7-$G13,0,1,1),Data!$A:$A,Data!$G:$G)-(AF$8+AF$9*_xlfn.XLOOKUP(OFFSET(Data!$A$1,AF$7-$G13,0,1,1),Data!$A:$A,Data!$F:$F)) -> -0.0085557322 | AG13: =_xlfn.XLOOKUP(OFFSET(Data!$A$1,AG$7-$G13,0,1,1),Data!$A:$A,Data!$H:$H)-(AG$8+AG$9*_xlfn.XLOOKUP(OFFSET(Data!$A$1,AG$7-$G13,0,1,1),Data!$A:$A,Data!$F:$F)) -> -0.017615961 | AH13: =_xlfn.XLOOKUP(OFFSET(Data!$A$1,AH$7-$G13,0,1,1),Data!$A:$A,Data!$I:$I)-(AH$8+AH$9*_xlfn.XLOOKUP(OFFSET(Data!$A$1,AH$7-$G13,0,1,1),Data!$A:$A,Data!$F:$F)) -> 0.034556962 | AI13: =_xlfn.XLOOKUP(OFFSET(Data!$A$1,AI$7-$G13,0,1,1),Data!$A:$A,Data!$G:$G)-(AI$8+AI$9*_xlfn.XLOOKUP(OFFSET(Data!$A$1,AI$7-$G13,0,1,1),Data!$A:$A,Data!$F:$F)) -> -0.0025781083 | AJ13: =_xlfn.XLOOKUP(OFFSET(Data!$A$1,AJ$7-$G13,0,1,1),Data!$A:$A,Data!$H:$H)-(AJ$8+AJ$9*_xlfn.XLOOKUP(OFFSET(Data!$A$1,AJ$7-$G13,0,1,1),Data!$A:$A,Data!$F:$F)) -> -0.00041635649 | AK13: =_xlfn.XLOOKUP(OFFSET(Data!$A$1,AK$7-$G13,0,1,1),Data!$A:$A,Data!$I:$I)-(AK$8+AK$9*_xlfn.XLOOKUP(OFFSET(Data!$A$1,AK$7-$G13,0,1,1),Data!$A:$A,Data!$F:$F)) -> 0.012264403 | AL13: =_xlfn.XLOOKUP(OFFSET(Data!$A$1,AL$7-$G13,0,1,1),Data!$A:$A,Data!$G:$G)-(AL$8+AL$9*_xlfn.XLOOKUP(OFFSET(Data!$A$1,AL$7-$G13,0,1,1),Data!$A:$A,Data!$F:$F)) -> 0.0044697865 | AM13: =_xlfn.XLOOKUP(OFFSET(Data!$A$1,AM$7-$G13,0,1,1),Data!$A:$A,Data!$H:$H)-(AM$8+AM$9*_xlfn.XLOOKUP(OFFSET(Data!$A$1,AM$7-$G13,0,1,1),Data!$A:$A,Data!$F:$F)) -> 0.022221587 | AN13: =_xlfn.XLOOKUP(OFFSET(Data!$A$1,AN$7-$G13,0,1,1),Data!$A:$A,Data!$I:$I)-(AN$8+AN$9*_xlfn.XLOOKUP(OFFSET(Data!$A$1,AN$7-$G13,0,1,1),Data!$A:$A,Data!$F:$F)) -> -0.017554665 | AO13: =_xlfn.XLOOKUP(OFFSET(Data!$A$1,AO$7-$G13,0,1,1),Data!$A:$A,Data!$G:$G)-(AO$8+AO$9*_xlfn.XLOOKUP(OFFSET(Data!$A$1,AO$7-$G13,0,1,1),Data!$A:$A,Data!$F:$F)) -> 0.037012011 | AP13: =_xlfn.XLOOKUP(OFFSET(Data!$A$1,AP$7-$G13,0,1,1),Data!$A:$A,Data!$H:$H)-(AP$8+AP$9*_xlfn.XLOOKUP(OFFSET(Data!$A$1,AP$7-$G13,0,1,1),Data!$A:$A,Data!$F:$F)) -> 0.010792991 | AQ13: =_xlfn.XLOOKUP(OFFSET(Data!$A$1,AQ$7-$G13,0,1,1),Data!$A:$A,Data!$I:$I)-(AQ$8+AQ$9*_xlfn.XLOOKUP(OFFSET(Data!$A$1,AQ$7-$G13,0,1,1),Data!$A:$A,Data!$F:$F)) -> -0.00047408939 | AS13: 0 | AT13: =AVERAGEIF($H$5:$AQ$5,"+",$H23:$AQ23) -> 0.0022254998 | AU13: {=SQRT(SUMPRODUCT(($H$5:$AQ$5="+")*($H23:$AQ23-AT13)^2)/(AY13-1))/SQRT(AY13)} -> 0.0077668369 | AV13: =AT13/AU13 -> 0.28653876 | AW13: =IF(ABS(AV13)<1.96,"No","Yes") -> No | AX13: =(1+AX14)*(1+AT13)-1 -> 0.0045290656 | AY13: =COUNTIF($H$5:$AQ$5,"+") -> 18 | BA13: 0 | BB13: =AVERAGEIF($H$5:$AQ$5,"-",$H23:$AQ23) -> -0.0098457145 | BC13: {=SQRT(SUMPRODUCT(($H$5:$AQ$5="-")*($H23:$AQ23-BB13)^2)/(BG13-1))/SQRT(BG13)} -> 0.0043357266 | BD13: =BB13/BC13 -> -2.2708338 | BE13: =IF(ABS(BD13)<1.96,"No","Yes") -> Yes | BF13: =(1+BF14)*(1+BB13)-1 -> -0.017313705 | BG13: =COUNTIF($H$5:$AQ$5,"-") -> 18
